Workbook

Sheet Sheet1
A1: Id | B1: Hora de inicio | C1: Hora de finalización | D1: Correo electrónico | E1: Nombre | F1: FECHA | G1: FECHA KOMMO | H1: Asesor | I1: NOMBRE CLIENTE | J1: NSS | K1: CURP | L1: LEAD | M1: TELEFONO | N1: ESTATUS | O1: INFORMEDEPAGO | P1: DESCUENTOS | Q1: $0.30 | R1: CAPACIDAD | S1: VENCIMIENTO | T1: FINANCIERA | U1: Monto compra | V1: Asignado | W1: Fecha asignacion | X1: CUENTA PANTALLAS
B2: 46029.39 | C2: 46204.397 | D2: anónimo | F2: 46204 | G2: 28/06/2026 | H2: GLORIA ORTIZ C/C | I2: SILVESTRE VAZQUEZ PEREZ | J2: 71856308862 | L2: 22076120 | M2: 5219616687207 | N2: NUEVO MAYOR | O2: 7920.51 | Q2: 2376.15 | R2: 2376.15 | X2: 1
B3: 46029.403 | C3: 46204.404 | D3: anónimo | F3: 46204 | G3: 46270 | H3: KARLA GARCIA | I3: Santana Vazquez Martinez | K3: VAMS760419HTSZRN05 | L3: 20456384 | M3: 5218120225569 | N3: SIN CAPACIDAD | O3: 3404.17 | Q3: 1021.25 | R3: 0 | X3: 1
B4: 30/06/2026 17:26 | C4: 46204.406 | D4: anónimo | F4: 46204 | G4: 46029 | H4: VALERY RODRIGUEZ SUR | I4: MARTIN ESQUIVEL BASULTO | J4: 54805954010 | K4: EUBM590828HJCSSR02 | L4: 22155628 | M4: 5213221301995 | N4: COMPRA BIMESTRES | O4: 14368.93 | P4: 4307.82 | Q4: 4310.68 | R4: 2.86 | S4: 46393 | X4: 2
B5: 46029.419 | C5: 46204.425 | D5: anónimo | F5: 46204 | G5: 29/07/2026 | H5: IRAN CASTILLO SUR | I5: GUILLERMO GONZALEZ GUDIÑO | J5: 49866521245 | K5: GOGG650509HTSNDL06 | L5: 22099170 | M5: 22099170 | N5: NUEVO MAYOR | O5: 26776.92 | Q5: 8033.08 | R5: 8033.08 | X5: 1
B6: 46029.425 | C6: 46204.429 | D6: anónimo | F6: 46204 | G6: 46029 | H6: MIRIAM MONTELONGO SUR | I6: MAXIMINO SALUSTIANO ORTEGA VASQUEZ | J6: 78856505439 | K6: OEVM650608HOCRSX02 | L6: 22161070 | M6: 5219541288949 | N6: NUEVO MAYOR | O6: 9760.32 | Q6: 2928.1 | R6: 2928.1 | X6: 1
B7: 46029.403 | C7: 46204.43 | D7: anónimo | F7: 46204 | G7: 30/06/2026 | H7: GLORIA ORTIZ C/C | I7: JOSE PALACIOS ALVAREZ | J7: 31795905855 | L7: 22125836 | M7: 5216182035940 | N7: NUEVO MENOR | O7: 4568.18 | Q7: 1370.45 | R7: 395.2 | X7: 1
B8: 46029.44 | C8: 46204.442 | D8: anónimo | F8: 46204 | G8: 46029 | H8: DULCE ARTEAGA SUR | I8: ALBERTO RODRIGUEZ SALAS | J8: 43755642246 | K8: ROSA560606HNLDLL04 | L8: 22161170 | M8: 5218120653677 | N8: COMPRA BIMESTRES | O8: 7095.3 | P8: 2128.59 | Q8: 2128.59 | R8: 0 | S8: 46755 | X8: 2
B9: 46029.465 | C9: 46204.466 | D9: anónimo | F9: 46204 | G9: 46029 | H9: ROSA CASTRO SUR | I9: MARCOS CUEVAS PUGA | J9: 4866321724 | K9: CUPM630425HJCVGR00 | L9: 22152008 | M9: 22152008 | N9: SIN CAPACIDAD | O9: 4199.87 | P9: 848 | Q9: 1259.96 | R9: -821.11 | X9: 1
B10: 46029.421 | C10: 46204.472 | D10: anónimo | F10: 46204 | G10: 46029 | H10: ESMERALDA ESQUIVEL SUR | I10: Lorena Cedillo Saldivar | J10: 32796100967 | K10: CESL611222MCLDLR09 | L10: 22164328 | M10: 22164328 | N10: COMPRA BIMESTRES | O10: 6262.86 | P10: 1876.17 | Q10: 1878.86 | R10: 2.69 | S10: 46759 | X10: 2
B11: 46029.479 | C11: 46204.481 | D11: anónimo | F11: 46204 | G11: 46029 | H11: DULCE ARTEAGA SUR | I11: HUMBERTO MORAN ROCHIN | K11: MORH570325HSLRCM08 | L11: 22166130 | M11: 5216674133739 | N11: SIN CAPACIDAD | O11: 4199.87 | Q11: 1259.96 | R11: 26.89 | X11: 1
B12: 46029.466 | C12: 46204.484 | D12: anónimo | F12: 46204 | G12: 46029 | H12: ROSA CASTRO SUR | I12: JORGE RIVAS MURILLO | J12: 63806022404 | K12: RIMJ600326HDFVRR09 | L12: 22160456 | M12: 5219981553770 | N12: COMPRA BIMESTRES | O12: 34491.44 | P12: 10346 | Q12: 10347.43 | R12: 1.43 | S12: 46758 | X12: 2
B13: 46029.469 | C13: 46204.489 | D13: anónimo | F13: 46204 | G13: 30/06/2026 | H13: DULCE FRANCO | I13: JUANA ARACELI HERNANDEZ HERNANDEZ | K13: HEHJ650819MDGRRN07 | L13: 22120944 | M13: 8114757799 | N13: COMPRA BIMESTRES | O13: 9760.32 | P13: 2900 | Q13: 2928.1 | R13: 28.1 | S13: 46754 | X13: 2
B14: 30/06/2026 16:00 | C14: 46204.491 | D14: anónimo | F14: 46204 | G14: 28/06/2026 | H14: MARIA NIÑO | I14: IGNACIO MEDINA FERRETIZ | K14: MEFI550312HSPDRG00 | L14: 22072350 | M14: 19452607843 | N14: NUEVO MAYOR | O14: 5630.32 | Q14: 1689.1 | R14: 1457.34 | X14: 1
B15: 46029.493 | C15: 46204.494 | D15: anónimo | F15: 46204 | G15: 46029 | H15: MARA HERNANDEZ SUR | I15: Martha Isabel Santos Barrios | J15: 31805908899 | K15: SABM621029MDGNRR05 | L15: 22166586 | M15: 5216188396640 | N15: SIN CAPACIDAD | O15: 4172.79 | P15: 340.49 | Q15: 1251.84 | R15: -340.49 | X15: 1
B16: 46029.335 | C16: 46204.494 | D16: anónimo | F16: 46204 | G16: 28/06/2026 | H16: LITZY MARTINEZ C/C | I16: NORMA TERRONES | J16: 12988266677 | K16: LOPJ821011HGTPXN04 | L16: 22071972 | M16: 4111160847 | N16: LEY 97 | Q16: 0 | R16: 0 | X16: 1
B17: 46029.499 | C17: 46204.499 | D17: anónimo | F17: 46204 | G17: 46029 | H17: FERNANDA ROMERO SUR | I17: RICARDO REYES ZAMORA | K17: REZR630521HVZYMC00 | L17: 22166364 | M17: 5214461381127 | N17: COMPRA BIMESTRES | O17: 12125.36 | P17: 3637.57 | Q17: 3637.61 | R17: 0.04 | S17: 46399 | X17: 2
B18: 46029.499 | C18: 46204.501 | D18: anónimo | F18: 46204 | G18: 46029 | H18: LILIANA MARTINEZ SUR | I18: MARIA GUADALUPE TIZNADO DELGADILLO | K18: TIDG840223MBCZLD05 | L18: 22165772 | M18: 5216861876635 | N18: LEY 97 | Q18: 0 | R18: 0 | X18: 1
B19: 46029.509 | C19: 46204.512 | D19: anónimo | F19: 46204 | G19: 46029 | H19: XIMENA RIVERA SUR | I19: JESUS IMELDO OROZCO PEREZ | J19: 11905802002 | K19: OOPJ580513HDFRRS02 | L19: 22165722 | M19: 5215554990813 | N19: COMPRA BIMESTRES | O19: 9081.52 | P19: 2520 | Q19: 2724.46 | R19: 204.46 | S19: 46759 | T19: OPCIPRES | X19: 2
B20: 46029.518 | C20: 46204.519 | D20: anónimo | F20: 46204 | G20: 46029 | H20: MIRIAM MONTELONGO SUR | I20: CARLOS HERNANDEZ MALDONADO | K20: HEMC581103HTSRLR02 | L20: 22159260 | M20: 22159260 | N20: COMPRA BIMESTRES | O20: 6262.86 | P20: 1811.23 | Q20: 1878.86 | R20: 67.63 | S20: 46397 | X20: 2
B21: 46029.512 | C21: 46204.522 | D21: anónimo | F21: 46204 | G21: 30/06/2026 | H21: JORGE MEDINA EXT C/C | I21: MANUEL IZMAEL CAB UUH | J21: 84816307601 | K21: CAUM630617HYNBHN05 | L21: 22106562 | M21: 5219871019830 | N21: NUEVO MAYOR | O21: 7920.51 | P21: 848 | Q21: 2376.15 | R21: 1528.15 | X21: 1
B22: 46029.526 | C22: 46204.526 | D22: anónimo | F22: 46204 | G22: 46029 | H22: ALBERTO POZOS EXT | J22: 219473515530 | L22: 1 | N22: COMPRA BIMESTRES | O22: 8895.06 | P22: 2583.69 | Q22: 2668.52 | R22: 84.83 | S22: 46033 | X22: 2
B23: 46029.546 | C23: 46204.547 | D23: anónimo | F23: 46204 | G23: 46029 | H23: LILIANA MARTINEZ SUR | I23: JEUS AMARO FLORES | J23: 43816503825 | K23: AAFJ650316HNLMLS05 | L23: 22167414 | M23: 5218186939401 | N23: NUEVO MAYOR | O23: 9760.32 | Q23: 2928.1 | R23: 2928.1 | X23: 1
B24: 46029.544 | C24: 46204.55 | D24: anónimo | F24: 46204 | G24: 30/06/2026 | H24: HANIA GARCIA | I24: Ana Maria Barrera Lopez | J24: 10836512557 | K24: BALA650726MMCRPN01 | L24: 22120886 | M24: 5543518301 | N24: COMPRA BIMESTRES | O24: 5055.87 | P24: 1200.07 | Q24: 1516.76 | R24: -317.18 | S24: 46357 | X24: 2
B25: 46029.484 | C25: 46204.558 | D25: anónimo | F25: 46204 | G25: 46029 | H25: ROSA CASTRO SUR | I25: ROSIO BEATRIZ CHAN EK | J25: 84997407659 | K25: CAER740528MYNHKS10 | L25: 22153394 | M25: 22153394 | N25: NO DATO | Q25: 0 | R25: 0 | X25: 0
B26: 46029.552 | C26: 46204.558 | D26: anónimo | F26: 46204 | G26: 46029 | H26: IRAN CASTILLO SUR | I26: ANTONIO TORIJA MEJIA | J26: 63855700991 | K26: TOMA570127HDFRJN06 | L26: 22159482 | M26: 5215616196142 | N26: COMPRA BIMESTRES | O26: 9760.32 | P26: 2914.84 | Q26: 2928.1 | R26: 13.26 | S26: 46756 | X26: 2
B27: 46029.571 | C27: 46204.572 | D27: anónimo | F27: 46204 | G27: 28/06/2026 | H27: MARIA NIÑO | I27: RAMON LINO PARRA SABORI | K27: PASR600902HSRRBM00 | L27: 22073804 | M27: 5216624589761 | N27: COMPRA BIMESTRES | O27: 5617.63 | P27: 1392.55 | Q27: 1685.29 | R27: 52.1 | S27: 46390 | X27: 2
B28: 46029.527 | C28: 46204.574 | D28: anónimo | F28: 46204 | G28: 46029 | H28: ALAN ALTAMIRANO EXT | I28: ALFREDO ZAVALA TUDON | K28: ZATA620612HTSVDL03 | L28: 1 | M28: 8683945967 | N28: COMPRA MAYOR | O28: 7920.51 | P28: 2182.22 | Q28: 2376.15 | R28: 193.93 | S28: 46027 | X28: 2
B29: 46029.581 | C29: 46204.583 | D29: anónimo | F29: 46204 | G29: 30/06/2026 | H29: DEYANIRA CORDOVA C/C | I29: MARIO | K29: MEHM641116HCLNRR04 | L29: 22125834 | M29: 8445409780 | N29: NUEVO MAYOR | O29: 9081.52 | Q29: 2724.46 | R29: 2724.46 | X29: 1
B30: 46029.585 | C30: 46204.586 | D30: anónimo | F30: 46204 | G30: 30/06/2026 | H30: ANA VILLEGAS C/C | I30: LILIA | J30: 32907377710 | K30: PESL741120MCLRFL03 | L30: 22128748 | M30: 5218262641856 | N30: COMPRA BIMESTRES | O30: 7118.1 | P30: 2134.47 | Q30: 2135.43 | R30: 0.96 | S30: 46266 | X30: 2
B31: 46029.586 | C31: 46204.588 | D31: anónimo | F31: 46204 | G31: 30/06/2026 | H31: ANA VILLEGAS C/C | I31: Fernando madera | J31: 1735247338 | L31: 22125778 | M31: 5214931259332 | N31: NUEVO MAYOR | O31: 23893.01 | Q31: 7167.9 | R31: 7167.9 | X31: 1
B32: 46029.588 | C32: 46204.59 | D32: anónimo | F32: 46204 | G32: 30/06/2026 | H32: ANA VILLEGAS C/C | I32: JORGE PEREZ | K32: PEOJ600728HDFRLR01 | L32: 22129186 | M32: 5215619415489 | N32: SIN CAPACIDAD | O32: 4199.87 | P32: 848 | Q32: 1259.96 | R32: -821.11 | X32: 1
B33: 46029.59 | C33: 46204.591 | D33: anónimo | F33: 46204 | G33: 30/06/2026 | H33: ANA VILLEGAS C/C | I33: José Juan Félix | J33: 23846009217 | L33: 22128306 | M33: 5216871965719 | N33: NUEVO MENOR | O33: 26507.99 | P33: 6796.9 | Q33: 7952.4 | R33: 1155.5 | S33: 46398 | X33: 2
B34: 46029.59 | C34: 46204.597 | D34: anónimo | F34: 46204 | G34: 28/06/2026 | H34: MERARI PEREZ | I34: NEREO REYES LOPEZ | J34: 82805601448 | K34: RELN560907HVZYPR08 | L34: 22075284 | M34: 22075284 | N34: COMPRA BIMESTRES | O34: 4813.69 | P34: 617.9 | Q34: 1444.11 | R34: 22.81 | S34: 46398 | X34: 2
B35: 46029.569 | C35: 46204.597 | D35: anónimo | F35: 46204 | G35: 46029 | H35: IRAN CASTILLO SUR | I35: JOSE CRUZ LOPEZ CRUZ | J35: 32684816609 | K35: LOCC480503HCLPRR01 | L35: 22161372 | M35: 5218446085551 | N35: COMPRA BIMESTRES | O35: 10020.03 | P35: 3005.41 | Q35: 3006.01 | R35: 0.6 | S35: 46398 | X35: 2
B36: 46029.601 | C36: 46204.603 | D36: anónimo | F36: 46204 | G36: 46029 | H36: IRAN CASTILLO SUR | I36: JOSE ANGEL LOPEZ CASAS | K36: LXCA621017HNLPSN09 | L36: 22162412 | M36: 5214881170727 | N36: COMPRA MAYOR | O36: 9081.52 | P36: 2518.66 | Q36: 2724.46 | R36: 205.8 | S36: 46029 | X36: 2
B37: 46029.372 | C37: 46204.608 | D37: anónimo | F37: 46204 | G37: 46029 | H37: YAMILETH LÓPEZ HDEZ SUR | I37: ANICETO RODOLFO BELTRAN CORIA | J37: 42806382356 | K37: BECA630417HMSLRN02 | L37: 22172958 | M37: 5217351614271 | N37: COMPRA BIMESTRES | O37: 10750.17 | P37: 3224.13 | Q37: 3225.05 | R37: 0.92 | S37: 46389 | X37: 2
B38: 46029.607 | C38: 46204.61 | D38: anónimo | F38: 46204 | G38: 30/06/2026 | H38: DEYANIRA CORDOVA C/C | J38: 33806434180 | L38: 22126200 | M38: 6391558331 | N38: COMPRA MAYOR | O38: 18771.99 | P38: 5333.7 | Q38: 5631.6 | R38: 297.9 | S38: 46029 | X38: 2
B39: 46029.612 | C39: 46204.615 | D39: anónimo | F39: 46204 | G39: 30/06/2026 | H39: MARIA MARTINEZ SUR | I39: BEATRIZ HERNANDEZ RODRIGUEZ | J39: 60836000467 | K39: HERB600202MDFRDT00 | L39: 22151900 | M39: 5215578381289 | N39: COMPRA MENOR | O39: 5617.63 | P39: 1392.9 | Q39: 1685.29 | R39: 51.75 | S39: 46027 | X39: 2
B40: 46029.619 | C40: 46204.624 | D40: anónimo | F40: 46204 | G40: 30/06/2026 | H40: MERARI PEREZ | I40: CARLOS MARTINEZ CRUZ | J40: 14806007622 | K40: MACC601124HQTRRR08 | L40: 22120712 | M40: 5214142191750 | N40: COMPRA BIMESTRES | O40: 7116.73 | P40: 2057.73 | Q40: 2135.02 | R40: 77.29 | S40: 46394 | X40: 2
...

Sheet REPOTEADOR
A1: FECHA | B1: 46289
A3: Recuento de ESTATUS | B3: ESTATUS
A4: Asesor | B4: NUEVO MAYOR | C4: NUEVO MENOR | D4: COMPRA MAYOR | E4: COMPRA MENOR | F4: RESTRINGIDA | G4: Total general
A5: CLAUDIA LAGUNES | B5: 2 | F5: 1 | G5: 3
A6: GIOVANNI MELGAR | B6: 3 | C6: 1 | G6: 4
A7: GUADALUPE CRUZ SUR | B7: 1 | D7: 1 | E7: 1 | G7: 3
A8: JAEL RUIZ | F8: 1 | G8: 1
A9: ROSA CASTRO SUR | B9: 1 | G9: 1
A10: RUTH MARTINEZ SUR | B10: 2 | G10: 2
A11: Total general | B11: 9 | C11: 1 | D11: 1 | E11: 1 | F11: 2 | G11: 14

Sheet Hoja1
A1: ALAN ALTAMIRANO EXT
A2: MAGALI MARTINEZ EXT 2
A3: YAMILETH CARDONA EXT 2
A4: PAOLA RODRIGUEZ C/C
A5: GLORIA ORTIZ C/C
A6: GIOVANNI MELGAR
A7: ROSA CASTRO SUR
A8: LILIANA MARTINEZ SUR
A9: BEATRIZ DE LA CRUZ C/C
A10: ANA VILLEGAS C/C
A11: DEYANIRA CORDOVA C/C
A12: GUADALUPE BECERRA C/C
... A15: DULCE FRANCO C/C

Sheet REPORTE GENERAL
B1: FECHA | C1: 46293
A3: ASESOR | B3: NUEVO MAYOR | C3: NUEVO MENOR | D3: COMPRA MAYOR | E3: COMPRA MENOR | F3: RESTRINGIDA | G3: COMPRA BIMESTRES | H3: SIN CAPACIDAD | I3: SIN NOMINA | J3: LEY 97 | K3: NO DATO | L3: NEGOCIO DUPLICADO | M3: Total general
A4: ANDRE TREVIÑO C/C | B4: =COUNTIFS(Sheet1!F:F,'REPORTE GENERAL'!C$1,Sheet1!N:N,'REPORTE GENERAL'!B$3,Sheet1!H:H,'REPORTE GENERAL'!A4) -> 0 | C4: =COUNTIFS(Sheet1!F:F,'REPORTE GENERAL'!C$1,Sheet1!N:N,'REPORTE GENERAL'!C$3,Sheet1!H:H,'REPORTE GENERAL'!A4) -> 0 | D4: =COUNTIFS(Sheet1!F:F,'REPORTE GENERAL'!C$1,Sheet1!N:N,'REPORTE GENERAL'!D$3,Sheet1!H:H,'REPORTE GENERAL'!A4) -> 0 | E4: =COUNTIFS(Sheet1!F:F,'REPORTE GENERAL'!C$1,Sheet1!N:N,'REPORTE GENERAL'!E$3,Sheet1!H:H,'REPORTE GENERAL'!A4) -> 0 | F4: =COUNTIFS(Sheet1!F:F,'REPORTE GENERAL'!C$1,Sheet1!N:N,'REPORTE GENERAL'!F$3,Sheet1!H:H,'REPORTE GENERAL'!A4) -> 0 | G4: =COUNTIFS(Sheet1!F:F,'REPORTE GENERAL'!C$1,Sheet1!N:N,'REPORTE GENERAL'!G$3,Sheet1!H:H,'REPORTE GENERAL'!A4) -> 0 | H4: =COUNTIFS(Sheet1!F:F,'REPORTE GENERAL'!C$1,Sheet1!N:N,'REPORTE GENERAL'!H$3,Sheet1!H:H,'REPORTE GENERAL'!A4) -> 0 | I4: =COUNTIFS(Sheet1!F:F,'REPORTE GENERAL'!C$1,Sheet1!N:N,'REPORTE GENERAL'!I$3,Sheet1!H:H,'REPORTE GENERAL'!A4) -> 0 | J4: =COUNTIFS(Sheet1!F:F,'REPORTE GENERAL'!C$1,Sheet1!N:N,'REPORTE GENERAL'!J$3,Sheet1!H:H,'REPORTE GENERAL'!A4) -> 0 | K4: =COUNTIFS(Sheet1!F:F,'REPORTE GENERAL'!C$1,Sheet1!N:N,'REPORTE GENERAL'!K$3,Sheet1!H:H,'REPORTE GENERAL'!A4) -> 0 | L4: =COUNTIFS(Sheet1!F:F,'REPORTE GENERAL'!C$1,Sheet1!N:N,'REPORTE GENERAL'!L$3,Sheet1!H:H,'REPORTE GENERAL'!A4) -> 0 | M4: =SUM(B4:L4) -> 0
A5: ANA VILLEGAS C/C | B5: =COUNTIFS(Sheet1!F:F,'REPORTE GENERAL'!C$1,Sheet1!N:N,'REPORTE GENERAL'!B$3,Sheet1!H:H,'REPORTE GENERAL'!A5) -> 0 | C5: =COUNTIFS(Sheet1!F:F,'REPORTE GENERAL'!C$1,Sheet1!N:N,'REPORTE GENERAL'!C$3,Sheet1!H:H,'REPORTE GENERAL'!A5) -> 0 | D5: =COUNTIFS(Sheet1!F:F,'REPORTE GENERAL'!C$1,Sheet1!N:N,'REPORTE GENERAL'!D$3,Sheet1!H:H,'REPORTE GENERAL'!A5) -> 0 | E5: =COUNTIFS(Sheet1!F:F,'REPORTE GENERAL'!C$1,Sheet1!N:N,'REPORTE GENERAL'!E$3,Sheet1!H:H,'REPORTE GENERAL'!A5) -> 0 | F5: =COUNTIFS(Sheet1!F:F,'REPORTE GENERAL'!C$1,Sheet1!N:N,'REPORTE GENERAL'!F$3,Sheet1!H:H,'REPORTE GENERAL'!A5) -> 0 | G5: =COUNTIFS(Sheet1!F:F,'REPORTE GENERAL'!C$1,Sheet1!N:N,'REPORTE GENERAL'!G$3,Sheet1!H:H,'REPORTE GENERAL'!A5) -> 0 | H5: =COUNTIFS(Sheet1!F:F,'REPORTE GENERAL'!C$1,Sheet1!N:N,'REPORTE GENERAL'!H$3,Sheet1!H:H,'REPORTE GENERAL'!A5) -> 0 | I5: =COUNTIFS(Sheet1!F:F,'REPORTE GENERAL'!C$1,Sheet1!N:N,'REPORTE GENERAL'!I$3,Sheet1!H:H,'REPORTE GENERAL'!A5) -> 0 | J5: =COUNTIFS(Sheet1!F:F,'REPORTE GENERAL'!C$1,Sheet1!N:N,'REPORTE GENERAL'!J$3,Sheet1!H:H,'REPORTE GENERAL'!A5) -> 0 | K5: =COUNTIFS(Sheet1!F:F,'REPORTE GENERAL'!C$1,Sheet1!N:N,'REPORTE GENERAL'!K$3,Sheet1!H:H,'REPORTE GENERAL'!A5) -> 0 | L5: =COUNTIFS(Sheet1!F:F,'REPORTE GENERAL'!C$1,Sheet1!N:N,'REPORTE GENERAL'!L$3,Sheet1!H:H,'REPORTE GENERAL'!A5) -> 0 | M5: =SUM(B5:L5) -> 0
A6: GLORIA ORTIZ C/C | B6: =COUNTIFS(Sheet1!F:F,'REPORTE GENERAL'!C$1,Sheet1!N:N,'REPORTE GENERAL'!B$3,Sheet1!H:H,'REPORTE GENERAL'!A6) -> 0 | C6: =COUNTIFS(Sheet1!F:F,'REPORTE GENERAL'!C$1,Sheet1!N:N,'REPORTE GENERAL'!C$3,Sheet1!H:H,'REPORTE GENERAL'!A6) -> 0 | D6: =COUNTIFS(Sheet1!F:F,'REPORTE GENERAL'!C$1,Sheet1!N:N,'REPORTE GENERAL'!D$3,Sheet1!H:H,'REPORTE GENERAL'!A6) -> 0 | E6: =COUNTIFS(Sheet1!F:F,'REPORTE GENERAL'!C$1,Sheet1!N:N,'REPORTE GENERAL'!E$3,Sheet1!H:H,'REPORTE GENERAL'!A6) -> 0 | F6: =COUNTIFS(Sheet1!F:F,'REPORTE GENERAL'!C$1,Sheet1!N:N,'REPORTE GENERAL'!F$3,Sheet1!H:H,'REPORTE GENERAL'!A6) -> 0 | G6: =COUNTIFS(Sheet1!F:F,'REPORTE GENERAL'!C$1,Sheet1!N:N,'REPORTE GENERAL'!G$3,Sheet1!H:H,'REPORTE GENERAL'!A6) -> 0 | H6: =COUNTIFS(Sheet1!F:F,'REPORTE GENERAL'!C$1,Sheet1!N:N,'REPORTE GENERAL'!H$3,Sheet1!H:H,'REPORTE GENERAL'!A6) -> 0 | I6: =COUNTIFS(Sheet1!F:F,'REPORTE GENERAL'!C$1,Sheet1!N:N,'REPORTE GENERAL'!I$3,Sheet1!H:H,'REPORTE GENERAL'!A6) -> 0 | J6: =COUNTIFS(Sheet1!F:F,'REPORTE GENERAL'!C$1,Sheet1!N:N,'REPORTE GENERAL'!J$3,Sheet1!H:H,'REPORTE GENERAL'!A6) -> 0 | K6: =COUNTIFS(Sheet1!F:F,'REPORTE GENERAL'!C$1,Sheet1!N:N,'REPORTE GENERAL'!K$3,Sheet1!H:H,'REPORTE GENERAL'!A6) -> 0 | L6: =COUNTIFS(Sheet1!F:F,'REPORTE GENERAL'!C$1,Sheet1!N:N,'REPORTE GENERAL'!L$3,Sheet1!H:H,'REPORTE GENERAL'!A6) -> 0 | M6: =SUM(B6:L6) -> 0
A7: CAROLINA RAMIREZ C/C | B7: =COUNTIFS(Sheet1!F:F,'REPORTE GENERAL'!C$1,Sheet1!N:N,'REPORTE GENERAL'!B$3,Sheet1!H:H,'REPORTE GENERAL'!A7) -> 0 | C7: =COUNTIFS(Sheet1!F:F,'REPORTE GENERAL'!C$1,Sheet1!N:N,'REPORTE GENERAL'!C$3,Sheet1!H:H,'REPORTE GENERAL'!A7) -> 0 | D7: =COUNTIFS(Sheet1!F:F,'REPORTE GENERAL'!C$1,Sheet1!N:N,'REPORTE GENERAL'!D$3,Sheet1!H:H,'REPORTE GENERAL'!A7) -> 0 | E7: =COUNTIFS(Sheet1!F:F,'REPORTE GENERAL'!C$1,Sheet1!N:N,'REPORTE GENERAL'!E$3,Sheet1!H:H,'REPORTE GENERAL'!A7) -> 0 | F7: =COUNTIFS(Sheet1!F:F,'REPORTE GENERAL'!C$1,Sheet1!N:N,'REPORTE GENERAL'!F$3,Sheet1!H:H,'REPORTE GENERAL'!A7) -> 0 | G7: =COUNTIFS(Sheet1!F:F,'REPORTE GENERAL'!C$1,Sheet1!N:N,'REPORTE GENERAL'!G$3,Sheet1!H:H,'REPORTE GENERAL'!A7) -> 0 | H7: =COUNTIFS(Sheet1!F:F,'REPORTE GENERAL'!C$1,Sheet1!N:N,'REPORTE GENERAL'!H$3,Sheet1!H:H,'REPORTE GENERAL'!A7) -> 0 | I7: =COUNTIFS(Sheet1!F:F,'REPORTE GENERAL'!C$1,Sheet1!N:N,'REPORTE GENERAL'!I$3,Sheet1!H:H,'REPORTE GENERAL'!A7) -> 0 | J7: =COUNTIFS(Sheet1!F:F,'REPORTE GENERAL'!C$1,Sheet1!N:N,'REPORTE GENERAL'!J$3,Sheet1!H:H,'REPORTE GENERAL'!A7) -> 0 | K7: =COUNTIFS(Sheet1!F:F,'REPORTE GENERAL'!C$1,Sheet1!N:N,'REPORTE GENERAL'!K$3,Sheet1!H:H,'REPORTE GENERAL'!A7) -> 0 | L7: =COUNTIFS(Sheet1!F:F,'REPORTE GENERAL'!C$1,Sheet1!N:N,'REPORTE GENERAL'!L$3,Sheet1!H:H,'REPORTE GENERAL'!A7) -> 0 | M7: =SUM(B7:L7) -> 0
A8: MARISOL HERNANDEZ C/C | B8: =COUNTIFS(Sheet1!F:F,'REPORTE GENERAL'!C$1,Sheet1!N:N,'REPORTE GENERAL'!B$3,Sheet1!H:H,'REPORTE GENERAL'!A8) -> 0 | C8: =COUNTIFS(Sheet1!F:F,'REPORTE GENERAL'!C$1,Sheet1!N:N,'REPORTE GENERAL'!C$3,Sheet1!H:H,'REPORTE GENERAL'!A8) -> 0 | D8: =COUNTIFS(Sheet1!F:F,'REPORTE GENERAL'!C$1,Sheet1!N:N,'REPORTE GENERAL'!D$3,Sheet1!H:H,'REPORTE GENERAL'!A8) -> 0 | E8: =COUNTIFS(Sheet1!F:F,'REPORTE GENERAL'!C$1,Sheet1!N:N,'REPORTE GENERAL'!E$3,Sheet1!H:H,'REPORTE GENERAL'!A8) -> 0 | F8: =COUNTIFS(Sheet1!F:F,'REPORTE GENERAL'!C$1,Sheet1!N:N,'REPORTE GENERAL'!F$3,Sheet1!H:H,'REPORTE GENERAL'!A8) -> 0 | G8: =COUNTIFS(Sheet1!F:F,'REPORTE GENERAL'!C$1,Sheet1!N:N,'REPORTE GENERAL'!G$3,Sheet1!H:H,'REPORTE GENERAL'!A8) -> 0 | H8: =COUNTIFS(Sheet1!F:F,'REPORTE GENERAL'!C$1,Sheet1!N:N,'REPORTE GENERAL'!H$3,Sheet1!H:H,'REPORTE GENERAL'!A8) -> 0 | I8: =COUNTIFS(Sheet1!F:F,'REPORTE GENERAL'!C$1,Sheet1!N:N,'REPORTE GENERAL'!I$3,Sheet1!H:H,'REPORTE GENERAL'!A8) -> 0 | J8: =COUNTIFS(Sheet1!F:F,'REPORTE GENERAL'!C$1,Sheet1!N:N,'REPORTE GENERAL'!J$3,Sheet1!H:H,'REPORTE GENERAL'!A8) -> 0 | K8: =COUNTIFS(Sheet1!F:F,'REPORTE GENERAL'!C$1,Sheet1!N:N,'REPORTE GENERAL'!K$3,Sheet1!H:H,'REPORTE GENERAL'!A8) -> 0 | L8: =COUNTIFS(Sheet1!F:F,'REPORTE GENERAL'!C$1,Sheet1!N:N,'REPORTE GENERAL'!L$3,Sheet1!H:H,'REPORTE GENERAL'!A8) -> 0 | M8: =SUM(B8:L8) -> 0
A9: MELANIE CIBRIAN C/C | B9: =COUNTIFS(Sheet1!F:F,'REPORTE GENERAL'!C$1,Sheet1!N:N,'REPORTE GENERAL'!B$3,Sheet1!H:H,'REPORTE GENERAL'!A9) -> 0 | C9: =COUNTIFS(Sheet1!F:F,'REPORTE GENERAL'!C$1,Sheet1!N:N,'REPORTE GENERAL'!C$3,Sheet1!H:H,'REPORTE GENERAL'!A9) -> 0 | D9: =COUNTIFS(Sheet1!F:F,'REPORTE GENERAL'!C$1,Sheet1!N:N,'REPORTE GENERAL'!D$3,Sheet1!H:H,'REPORTE GENERAL'!A9) -> 0 | E9: =COUNTIFS(Sheet1!F:F,'REPORTE GENERAL'!C$1,Sheet1!N:N,'REPORTE GENERAL'!E$3,Sheet1!H:H,'REPORTE GENERAL'!A9) -> 0 | F9: =COUNTIFS(Sheet1!F:F,'REPORTE GENERAL'!C$1,Sheet1!N:N,'REPORTE GENERAL'!F$3,Sheet1!H:H,'REPORTE GENERAL'!A9) -> 0 | G9: =COUNTIFS(Sheet1!F:F,'REPORTE GENERAL'!C$1,Sheet1!N:N,'REPORTE GENERAL'!G$3,Sheet1!H:H,'REPORTE GENERAL'!A9) -> 0 | H9: =COUNTIFS(Sheet1!F:F,'REPORTE GENERAL'!C$1,Sheet1!N:N,'REPORTE GENERAL'!H$3,Sheet1!H:H,'REPORTE GENERAL'!A9) -> 0 | I9: =COUNTIFS(Sheet1!F:F,'REPORTE GENERAL'!C$1,Sheet1!N:N,'REPORTE GENERAL'!I$3,Sheet1!H:H,'REPORTE GENERAL'!A9) -> 0 | J9: =COUNTIFS(Sheet1!F:F,'REPORTE GENERAL'!C$1,Sheet1!N:N,'REPORTE GENERAL'!J$3,Sheet1!H:H,'REPORTE GENERAL'!A9) -> 0 | K9: =COUNTIFS(Sheet1!F:F,'REPORTE GENERAL'!C$1,Sheet1!N:N,'REPORTE GENERAL'!K$3,Sheet1!H:H,'REPORTE GENERAL'!A9) -> 0 | L9: =COUNTIFS(Sheet1!F:F,'REPORTE GENERAL'!C$1,Sheet1!N:N,'REPORTE GENERAL'!L$3,Sheet1!H:H,'REPORTE GENERAL'!A9) -> 0 | M9: =SUM(B9:L9) -> 0
A10: FERNANDA CASTILLO C/C | B10: =COUNTIFS(Sheet1!F:F,'REPORTE GENERAL'!C$1,Sheet1!N:N,'REPORTE GENERAL'!B$3,Sheet1!H:H,'REPORTE GENERAL'!A10) -> 0 | C10: =COUNTIFS(Sheet1!F:F,'REPORTE GENERAL'!C$1,Sheet1!N:N,'REPORTE GENERAL'!C$3,Sheet1!H:H,'REPORTE GENERAL'!A10) -> 0 | D10: =COUNTIFS(Sheet1!F:F,'REPORTE GENERAL'!C$1,Sheet1!N:N,'REPORTE GENERAL'!D$3,Sheet1!H:H,'REPORTE GENERAL'!A10) -> 0 | E10: =COUNTIFS(Sheet1!F:F,'REPORTE GENERAL'!C$1,Sheet1!N:N,'REPORTE GENERAL'!E$3,Sheet1!H:H,'REPORTE GENERAL'!A10) -> 0 | F10: =COUNTIFS(Sheet1!F:F,'REPORTE GENERAL'!C$1,Sheet1!N:N,'REPORTE GENERAL'!F$3,Sheet1!H:H,'REPORTE GENERAL'!A10) -> 0 | G10: =COUNTIFS(Sheet1!F:F,'REPORTE GENERAL'!C$1,Sheet1!N:N,'REPORTE GENERAL'!G$3,Sheet1!H:H,'REPORTE GENERAL'!A10) -> 0 | H10: =COUNTIFS(Sheet1!F:F,'REPORTE GENERAL'!C$1,Sheet1!N:N,'REPORTE GENERAL'!H$3,Sheet1!H:H,'REPORTE GENERAL'!A10) -> 0 | I10: =COUNTIFS(Sheet1!F:F,'REPORTE GENERAL'!C$1,Sheet1!N:N,'REPORTE GENERAL'!I$3,Sheet1!H:H,'REPORTE GENERAL'!A10) -> 0 | J10: =COUNTIFS(Sheet1!F:F,'REPORTE GENERAL'!C$1,Sheet1!N:N,'REPORTE GENERAL'!J$3,Sheet1!H:H,'REPORTE GENERAL'!A10) -> 0 | K10: =COUNTIFS(Sheet1!F:F,'REPORTE GENERAL'!C$1,Sheet1!N:N,'REPORTE GENERAL'!K$3,Sheet1!H:H,'REPORTE GENERAL'!A10) -> 0 | L10: =COUNTIFS(Sheet1!F:F,'REPORTE GENERAL'!C$1,Sheet1!N:N,'REPORTE GENERAL'!L$3,Sheet1!H:H,'REPORTE GENERAL'!A10) -> 0 | M10: =SUM(B10:L10) -> 0
A11: PAOLA RODRIGUEZ C/C | B11: =COUNTIFS(Sheet1!F:F,'REPORTE GENERAL'!C$1,Sheet1!N:N,'REPORTE GENERAL'!B$3,Sheet1!H:H,'REPORTE GENERAL'!A11) -> 0 | C11: =COUNTIFS(Sheet1!F:F,'REPORTE GENERAL'!C$1,Sheet1!N:N,'REPORTE GENERAL'!C$3,Sheet1!H:H,'REPORTE GENERAL'!A11) -> 0 | D11: =COUNTIFS(Sheet1!F:F,'REPORTE GENERAL'!C$1,Sheet1!N:N,'REPORTE GENERAL'!D$3,Sheet1!H:H,'REPORTE GENERAL'!A11) -> 0 | E11: =COUNTIFS(Sheet1!F:F,'REPORTE GENERAL'!C$1,Sheet1!N:N,'REPORTE GENERAL'!E$3,Sheet1!H:H,'REPORTE GENERAL'!A11) -> 0 | F11: =COUNTIFS(Sheet1!F:F,'REPORTE GENERAL'!C$1,Sheet1!N:N,'REPORTE GENERAL'!F$3,Sheet1!H:H,'REPORTE GENERAL'!A11) -> 0 | G11: =COUNTIFS(Sheet1!F:F,'REPORTE GENERAL'!C$1,Sheet1!N:N,'REPORTE GENERAL'!G$3,Sheet1!H:H,'REPORTE GENERAL'!A11) -> 0 | H11: =COUNTIFS(Sheet1!F:F,'REPORTE GENERAL'!C$1,Sheet1!N:N,'REPORTE GENERAL'!H$3,Sheet1!H:H,'REPORTE GENERAL'!A11) -> 0 | I11: =COUNTIFS(Sheet1!F:F,'REPORTE GENERAL'!C$1,Sheet1!N:N,'REPORTE GENERAL'!I$3,Sheet1!H:H,'REPORTE GENERAL'!A11) -> 0 | J11: =COUNTIFS(Sheet1!F:F,'REPORTE GENERAL'!C$1,Sheet1!N:N,'REPORTE GENERAL'!J$3,Sheet1!H:H,'REPORTE GENERAL'!A11) -> 0 | K11: =COUNTIFS(Sheet1!F:F,'REPORTE GENERAL'!C$1,Sheet1!N:N,'REPORTE GENERAL'!K$3,Sheet1!H:H,'REPORTE GENERAL'!A11) -> 0 | L11: =COUNTIFS(Sheet1!F:F,'REPORTE GENERAL'!C$1,Sheet1!N:N,'REPORTE GENERAL'!L$3,Sheet1!H:H,'REPORTE GENERAL'!A11) -> 0 | M11: =SUM(B11:L11) -> 0
A12: MAGALI HERNANDEZ C/C | B12: =COUNTIFS(Sheet1!F:F,'REPORTE GENERAL'!C$1,Sheet1!N:N,'REPORTE GENERAL'!B$3,Sheet1!H:H,'REPORTE GENERAL'!A12) -> 0 | C12: =COUNTIFS(Sheet1!F:F,'REPORTE GENERAL'!C$1,Sheet1!N:N,'REPORTE GENERAL'!C$3,Sheet1!H:H,'REPORTE GENERAL'!A12) -> 0 | D12: =COUNTIFS(Sheet1!F:F,'REPORTE GENERAL'!C$1,Sheet1!N:N,'REPORTE GENERAL'!D$3,Sheet1!H:H,'REPORTE GENERAL'!A12) -> 0 | E12: =COUNTIFS(Sheet1!F:F,'REPORTE GENERAL'!C$1,Sheet1!N:N,'REPORTE GENERAL'!E$3,Sheet1!H:H,'REPORTE GENERAL'!A12) -> 0 | F12: =COUNTIFS(Sheet1!F:F,'REPORTE GENERAL'!C$1,Sheet1!N:N,'REPORTE GENERAL'!F$3,Sheet1!H:H,'REPORTE GENERAL'!A12) -> 0 | G12: =COUNTIFS(Sheet1!F:F,'REPORTE GENERAL'!C$1,Sheet1!N:N,'REPORTE GENERAL'!G$3,Sheet1!H:H,'REPORTE GENERAL'!A12) -> 0 | H12: =COUNTIFS(Sheet1!F:F,'REPORTE GENERAL'!C$1,Sheet1!N:N,'REPORTE GENERAL'!H$3,Sheet1!H:H,'REPORTE GENERAL'!A12) -> 0 | I12: =COUNTIFS(Sheet1!F:F,'REPORTE GENERAL'!C$1,Sheet1!N:N,'REPORTE GENERAL'!I$3,Sheet1!H:H,'REPORTE GENERAL'!A12) -> 0 | J12: =COUNTIFS(Sheet1!F:F,'REPORTE GENERAL'!C$1,Sheet1!N:N,'REPORTE GENERAL'!J$3,Sheet1!H:H,'REPORTE GENERAL'!A12) -> 0 | K12: =COUNTIFS(Sheet1!F:F,'REPORTE GENERAL'!C$1,Sheet1!N:N,'REPORTE GENERAL'!K$3,Sheet1!H:H,'REPORTE GENERAL'!A12) -> 0 | L12: =COUNTIFS(Sheet1!F:F,'REPORTE GENERAL'!C$1,Sheet1!N:N,'REPORTE GENERAL'!L$3,Sheet1!H:H,'REPORTE GENERAL'!A12) -> 0 | M12: =SUM(B12:L12) -> 0
A13: KARINA MATA C/C | B13: =COUNTIFS(Sheet1!F:F,'REPORTE GENERAL'!C$1,Sheet1!N:N,'REPORTE GENERAL'!B$3,Sheet1!H:H,'REPORTE GENERAL'!A13) -> 0 | C13: =COUNTIFS(Sheet1!F:F,'REPORTE GENERAL'!C$1,Sheet1!N:N,'REPORTE GENERAL'!C$3,Sheet1!H:H,'REPORTE GENERAL'!A13) -> 0 | D13: =COUNTIFS(Sheet1!F:F,'REPORTE GENERAL'!C$1,Sheet1!N:N,'REPORTE GENERAL'!D$3,Sheet1!H:H,'REPORTE GENERAL'!A13) -> 0 | E13: =COUNTIFS(Sheet1!F:F,'REPORTE GENERAL'!C$1,Sheet1!N:N,'REPORTE GENERAL'!E$3,Sheet1!H:H,'REPORTE GENERAL'!A13) -> 0 | F13: =COUNTIFS(Sheet1!F:F,'REPORTE GENERAL'!C$1,Sheet1!N:N,'REPORTE GENERAL'!F$3,Sheet1!H:H,'REPORTE GENERAL'!A13) -> 0 | G13: =COUNTIFS(Sheet1!F:F,'REPORTE GENERAL'!C$1,Sheet1!N:N,'REPORTE GENERAL'!G$3,Sheet1!H:H,'REPORTE GENERAL'!A13) -> 0 | H13: =COUNTIFS(Sheet1!F:F,'REPORTE GENERAL'!C$1,Sheet1!N:N,'REPORTE GENERAL'!H$3,Sheet1!H:H,'REPORTE GENERAL'!A13) -> 0 | I13: =COUNTIFS(Sheet1!F:F,'REPORTE GENERAL'!C$1,Sheet1!N:N,'REPORTE GENERAL'!I$3,Sheet1!H:H,'REPORTE GENERAL'!A13) -> 0 | J13: =COUNTIFS(Sheet1!F:F,'REPORTE GENERAL'!C$1,Sheet1!N:N,'REPORTE GENERAL'!J$3,Sheet1!H:H,'REPORTE GENERAL'!A13) -> 0 | K13: =COUNTIFS(Sheet1!F:F,'REPORTE GENERAL'!C$1,Sheet1!N:N,'REPORTE GENERAL'!K$3,Sheet1!H:H,'REPORTE GENERAL'!A13) -> 0 | L13: =COUNTIFS(Sheet1!F:F,'REPORTE GENERAL'!C$1,Sheet1!N:N,'REPORTE GENERAL'!L$3,Sheet1!H:H,'REPORTE GENERAL'!A13) -> 0 | M13: =SUM(B13:L13) -> 0
A14: CARRANZA SARDINA C/C | B14: =COUNTIFS(Sheet1!F:F,'REPORTE GENERAL'!C$1,Sheet1!N:N,'REPORTE GENERAL'!B$3,Sheet1!H:H,'REPORTE GENERAL'!A14) -> 0 | C14: =COUNTIFS(Sheet1!F:F,'REPORTE GENERAL'!C$1,Sheet1!N:N,'REPORTE GENERAL'!C$3,Sheet1!H:H,'REPORTE GENERAL'!A14) -> 0 | D14: =COUNTIFS(Sheet1!F:F,'REPORTE GENERAL'!C$1,Sheet1!N:N,'REPORTE GENERAL'!D$3,Sheet1!H:H,'REPORTE GENERAL'!A14) -> 0 | E14: =COUNTIFS(Sheet1!F:F,'REPORTE GENERAL'!C$1,Sheet1!N:N,'REPORTE GENERAL'!E$3,Sheet1!H:H,'REPORTE GENERAL'!A14) -> 0 | F14: =COUNTIFS(Sheet1!F:F,'REPORTE GENERAL'!C$1,Sheet1!N:N,'REPORTE GENERAL'!F$3,Sheet1!H:H,'REPORTE GENERAL'!A14) -> 0 | G14: =COUNTIFS(Sheet1!F:F,'REPORTE GENERAL'!C$1,Sheet1!N:N,'REPORTE GENERAL'!G$3,Sheet1!H:H,'REPORTE GENERAL'!A14) -> 0 | H14: =COUNTIFS(Sheet1!F:F,'REPORTE GENERAL'!C$1,Sheet1!N:N,'REPORTE GENERAL'!H$3,Sheet1!H:H,'REPORTE GENERAL'!A14) -> 0 | I14: =COUNTIFS(Sheet1!F:F,'REPORTE GENERAL'!C$1,Sheet1!N:N,'REPORTE GENERAL'!I$3,Sheet1!H:H,'REPORTE GENERAL'!A14) -> 0 | J14: =COUNTIFS(Sheet1!F:F,'REPORTE GENERAL'!C$1,Sheet1!N:N,'REPORTE GENERAL'!J$3,Sheet1!H:H,'REPORTE GENERAL'!A14) -> 0 | K14: =COUNTIFS(Sheet1!F:F,'REPORTE GENERAL'!C$1,Sheet1!N:N,'REPORTE GENERAL'!K$3,Sheet1!H:H,'REPORTE GENERAL'!A14) -> 0 | L14: =COUNTIFS(Sheet1!F:F,'REPORTE GENERAL'!C$1,Sheet1!N:N,'REPORTE GENERAL'!L$3,Sheet1!H:H,'REPORTE GENERAL'!A14) -> 0 | M14: =SUM(B14:L14) -> 0
A15: GIOVANNI MELGAR | B15: =COUNTIFS(Sheet1!F:F,'REPORTE GENERAL'!C$1,Sheet1!N:N,'REPORTE GENERAL'!B$3,Sheet1!H:H,'REPORTE GENERAL'!A15) -> 1 | C15: =COUNTIFS(Sheet1!F:F,'REPORTE GENERAL'!C$1,Sheet1!N:N,'REPORTE GENERAL'!C$3,Sheet1!H:H,'REPORTE GENERAL'!A15) -> 0 | D15: =COUNTIFS(Sheet1!F:F,'REPORTE GENERAL'!C$1,Sheet1!N:N,'REPORTE GENERAL'!D$3,Sheet1!H:H,'REPORTE GENERAL'!A15) -> 1 | E15: =COUNTIFS(Sheet1!F:F,'REPORTE GENERAL'!C$1,Sheet1!N:N,'REPORTE GENERAL'!E$3,Sheet1!H:H,'REPORTE GENERAL'!A15) -> 0 | F15: =COUNTIFS(Sheet1!F:F,'REPORTE GENERAL'!C$1,Sheet1!N:N,'REPORTE GENERAL'!F$3,Sheet1!H:H,'REPORTE GENERAL'!A15) -> 1 | G15: =COUNTIFS(Sheet1!F:F,'REPORTE GENERAL'!C$1,Sheet1!N:N,'REPORTE GENERAL'!G$3,Sheet1!H:H,'REPORTE GENERAL'!A15) -> 4 | H15: =COUNTIFS(Sheet1!F:F,'REPORTE GENERAL'!C$1,Sheet1!N:N,'REPORTE GENERAL'!H$3,Sheet1!H:H,'REPORTE GENERAL'!A15) -> 1 | I15: =COUNTIFS(Sheet1!F:F,'REPORTE GENERAL'!C$1,Sheet1!N:N,'REPORTE GENERAL'!I$3,Sheet1!H:H,'REPORTE GENERAL'!A15) -> 0 | J15: =COUNTIFS(Sheet1!F:F,'REPORTE GENERAL'!C$1,Sheet1!N:N,'REPORTE GENERAL'!J$3,Sheet1!H:H,'REPORTE GENERAL'!A15) -> 0 | K15: =COUNTIFS(Sheet1!F:F,'REPORTE GENERAL'!C$1,Sheet1!N:N,'REPORTE GENERAL'!K$3,Sheet1!H:H,'REPORTE GENERAL'!A15) -> 0 | L15: =COUNTIFS(Sheet1!F:F,'REPORTE GENERAL'!C$1,Sheet1!N:N,'REPORTE GENERAL'!L$3,Sheet1!H:H,'REPORTE GENERAL'!A15) -> 0 | M15: =SUM(B15:L15) -> 8
... A37: YAJAHIRA GONZALEZ EXT 2 | B37: =COUNTIFS(Sheet1!F:F,'REPORTE GENERAL'!C$1,Sheet1!N:N,'REPORTE GENERAL'!B$3,Sheet1!H:H,'REPORTE GENERAL'!A37) -> 0 | C37: =COUNTIFS(Sheet1!F:F,'REPORTE GENERAL'!C$1,Sheet1!N:N,'REPORTE GENERAL'!C$3,Sheet1!H:H,'REPORTE GENERAL'!A37) -> 0 | D37: =COUNTIFS(Sheet1!F:F,'REPORTE GENERAL'!C$1,Sheet1!N:N,'REPORTE GENERAL'!D$3,Sheet1!H:H,'REPORTE GENERAL'!A37) -> 0 | E37: =COUNTIFS(Sheet1!F:F,'REPORTE GENERAL'!C$1,Sheet1!N:N,'REPORTE GENERAL'!E$3,Sheet1!H:H,'REPORTE GENERAL'!A37) -> 0 | F37: =COUNTIFS(Sheet1!F:F,'REPORTE GENERAL'!C$1,Sheet1!N:N,'REPORTE GENERAL'!F$3,Sheet1!H:H,'REPORTE GENERAL'!A37) -> 0 | G37: =COUNTIFS(Sheet1!F:F,'REPORTE GENERAL'!C$1,Sheet1!N:N,'REPORTE GENERAL'!G$3,Sheet1!H:H,'REPORTE GENERAL'!A37) -> 0 | H37: =COUNTIFS(Sheet1!F:F,'REPORTE GENERAL'!C$1,Sheet1!N:N,'REPORTE GENERAL'!H$3,Sheet1!H:H,'REPORTE GENERAL'!A37) -> 0 | I37: =COUNTIFS(Sheet1!F:F,'REPORTE GENERAL'!C$1,Sheet1!N:N,'REPORTE GENERAL'!I$3,Sheet1!H:H,'REPORTE GENERAL'!A37) -> 0 | J37: =COUNTIFS(Sheet1!F:F,'REPORTE GENERAL'!C$1,Sheet1!N:N,'REPORTE GENERAL'!J$3,Sheet1!H:H,'REPORTE GENERAL'!A37) -> 0 | K37: =COUNTIFS(Sheet1!F:F,'REPORTE GENERAL'!C$1,Sheet1!N:N,'REPORTE GENERAL'!K$3,Sheet1!H:H,'REPORTE GENERAL'!A37) -> 0 | L37: =COUNTIFS(Sheet1!F:F,'REPORTE GENERAL'!C$1,Sheet1!N:N,'REPORTE GENERAL'!L$3,Sheet1!H:H,'REPORTE GENERAL'!A37) -> 0 | M37: =SUM(B37:L37) -> 0
A38: TOTAL | B38: =SUM(B5:B37) -> 6 | C38: =SUM(C5:C37) -> 4 | D38: =SUM(D5:D37) -> 3 | E38: =SUM(E5:E37) -> 0 | F38: =SUM(F5:F37) -> 1 | G38: =SUM(G5:G37) -> 16 | H38: =SUM(H5:H37) -> 7 | I38: =SUM(I5:I37) -> 0 | ... L38: =SUM(L5:L37) -> 0 | M38: =SUM(M4:M37) -> 39

Sheet Pant. Ext.
B2: ASESOR | C2: NSS | D2: CURP | E2: LEAD | F2: FECHA | G2: N PANTALLAS | H2: Columna1
B3: YESENIA | C3: 14846100163 | F3: 46227 | G3: 1
B4: YESENIA | D4: MOZM640320HDFYRR06 | F4: 46228 | G4: 2
B5: HECTOR | C5: 21806040461 | F5: 46230 | G5: 2
B6: HECTOR | C6: 32866405098 | F6: 46230 | G6: 2
B7: YESENIA | C7: 04826480438 | F7: 46233 | G7: 1
B8: HECTOR | C8: 32866405098 | F8: 46231 | G8: 2
B9: DEYANIRA | E9: 22584580 | F9: 46231 | G9: 1
B10: DEYANIRA | E10: 22756598 | F10: 46231 | G10: 1
B11: HECTOR | C11: 31796206113 | F11: 46234 | G11: 1
B12: YESENIA | C12: 3380640347-4 | F12: 46234 | G12: 3
B13: HECTOR | C13: 72937253150 | F13: 46234 | G13: 1
B15: YESENIA | C15: 3380624572 | F15: 46237 | G15: 1
B16: HECTOR | C16: 49784901016 | E16: 22895720 | F16: 46238 | G16: 2
B17: YESENIA | C17: 5380623599-9 | F17: 46238 | G17: 1
B18: HECTOR | C18: 24806243515 | F18: 46238 | G18: 2
B19: YESENIA | C19: 82876111590 | F19: 46239 | G19: 1
B20: YESENIA | C20: 7187640051-7 | F20: 46239 | G20: 1
B21: ANDRE | D21: CUPG640509HHGRRR02 | F21: 46239 | G21: 1
B22: HECTOR | C22: 10806273792 | F22: 46239 | G22: 1
B23: HECTOR | C23: 88805300253 | F23: 46240 | G23: 1
B24: HECTOR | C24: 32836570880 | F24: 46241 | G24: 1
B25: YESENIA | C25: 1287630124-8 | F25: 46242 | G25: 1
B26: HECTOR | C26: 14796320704 | F26: 46242 | G26: 1
B27: YESENIA | C27: 37886300013 | F27: 46244 | G27: 1
B28: YESENIA | C28: 1634756199 | F28: 46244 | G28: 1
B29: YESENIA | C29: 45917429859 | F29: 46244 | G29: 1
B30: YESENIA | C30: 06786036241 | F30: 46244 | G30: 1
B31: YESENIA | C31: 34816103914 | F31: 46244 | G31: 1
B32: HECTOR | C32: 49906546160 | F32: 46245 | G32: 1
B33: HECTOR | D33: LEAD650526MVZLRN09 | F33: 46245 | G33: 1
B34: YESENIA | C34: 67806335203 | F34: 46245 | G34: 1
B35: YESENIA | C35: 14765709317 | F35: 46245 | G35: 1
B36: YESENIA | C36: 33815731535 | F36: 46245 | G36: 1
B37: YESENIA | C37: 42906101359 | F37: 46246 | G37: 1
B38: HECTOR | C38: 01785985936 | F38: 46247 | G38: 1
B39: HECTOR | C39: 01685281030 | F39: 46247 | G39: 1
B40: LUIS DAVILA | C40: 32896525816 | D40: SOAM650728HCLLRR08 | F40: 46248 | G40: 2
B41: LUIS DAVILA | C41: 90897166659 | D41: Oilc710225hdfnps07 | F41: 46249 | G41: 1
B42: YESENIA | C42: 3397780162-1 | F42: 46252 | G42: 1
...

Sheet FILTRADO
A1: =Sheet1!A$1 -> Id | B1: =Sheet1!B$1 -> Hora de inicio | C1: =Sheet1!C$1 -> Hora de finalización | D1: =Sheet1!D$1 -> Correo electrónico | E1: =Sheet1!E$1 -> Nombre | F1: =Sheet1!F$1 -> FECHA | G1: =Sheet1!G$1 -> FECHA KOMMO | H1: =Sheet1!H$1 -> Asesor | ... T1: =Sheet1!T$1 -> FINANCIERA | U1: =Sheet1!V$1 -> Asignado | V1: =Sheet1!X$1 -> CUENTA PANTALLAS | AA1: ESTATUS INCLUIDOS
A2: {=_xlfn.LET(_xlpm.r,_xlfn._xlws.FILTER(OfficeForms.Table[],ISNUMBER(MATCH(OfficeForms.Table[ESTATUS],$AA$2:$AA$6,0)),"Sin resultados"),IF(_xlpm.r="","",_xlpm.r))} | B2: 46029.39 | C2: 46204.397 | D2: anónimo | F2: 46204 | G2: 28/06/2026 | H2: GLORIA ORTIZ C/C | I2: SILVESTRE VAZQUEZ PEREZ | J2: 71856308862 | L2: 22076120 | M2: 5219616687207 | N2: NUEVO MAYOR | O2: 7920.51 | Q2: 2376.15 | R2: 2376.15 | X2: 1 | AA2: NUEVO MAYOR
B3: 46029.419 | C3: 46204.425 | D3: anónimo | F3: 46204 | G3: 29/07/2026 | H3: IRAN CASTILLO SUR | I3: GUILLERMO GONZALEZ GUDIÑO | J3: 49866521245 | K3: GOGG650509HTSNDL06 | L3: 22099170 | M3: 22099170 | N3: NUEVO MAYOR | O3: 26776.92 | Q3: 8033.08 | R3: 8033.08 | X3: 1 | AA3: COMPRA MAYOR
B4: 46029.425 | C4: 46204.429 | D4: anónimo | F4: 46204 | G4: 46029 | H4: MIRIAM MONTELONGO SUR | I4: MAXIMINO SALUSTIANO ORTEGA VASQUEZ | J4: 78856505439 | K4: OEVM650608HOCRSX02 | L4: 22161070 | M4: 5219541288949 | N4: NUEVO MAYOR | O4: 9760.32 | Q4: 2928.1 | R4: 2928.1 | X4: 1 | AA4: NUEVO MENOR
B5: 46029.403 | C5: 46204.43 | D5: anónimo | F5: 46204 | G5: 30/06/2026 | H5: GLORIA ORTIZ C/C | I5: JOSE PALACIOS ALVAREZ | J5: 31795905855 | L5: 22125836 | M5: 5216182035940 | N5: NUEVO MENOR | O5: 4568.18 | Q5: 1370.45 | R5: 395.2 | X5: 1 | AA5: RESTRINGIDA
B6: 30/06/2026 16:00 | C6: 46204.491 | D6: anónimo | F6: 46204 | G6: 28/06/2026 | H6: MARIA NIÑO | I6: IGNACIO MEDINA FERRETIZ | K6: MEFI550312HSPDRG00 | L6: 22072350 | M6: 19452607843 | N6: NUEVO MAYOR | O6: 5630.32 | Q6: 1689.1 | R6: 1457.34 | X6: 1 | AA6: COMPRA MENOR
B7: 46029.512 | C7: 46204.522 | D7: anónimo | F7: 46204 | G7: 30/06/2026 | H7: JORGE MEDINA EXT C/C | I7: MANUEL IZMAEL CAB UUH | J7: 84816307601 | K7: CAUM630617HYNBHN05 | L7: 22106562 | M7: 5219871019830 | N7: NUEVO MAYOR | O7: 7920.51 | P7: 848 | Q7: 2376.15 | R7: 1528.15 | X7: 1 | AA7: Registros: | AB7: =COUNTA(A2:A100000) -> 1732
B8: 46029.546 | C8: 46204.547 | D8: anónimo | F8: 46204 | G8: 46029 | H8: LILIANA MARTINEZ SUR | I8: JEUS AMARO FLORES | J8: 43816503825 | K8: AAFJ650316HNLMLS05 | L8: 22167414 | M8: 5218186939401 | N8: NUEVO MAYOR | O8: 9760.32 | Q8: 2928.1 | R8: 2928.1 | X8: 1
B9: 46029.527 | C9: 46204.574 | D9: anónimo | F9: 46204 | G9: 46029 | H9: ALAN ALTAMIRANO EXT | I9: ALFREDO ZAVALA TUDON | K9: ZATA620612HTSVDL03 | L9: 1 | M9: 8683945967 | N9: COMPRA MAYOR | O9: 7920.51 | P9: 2182.22 | Q9: 2376.15 | R9: 193.93 | S9: 46027 | X9: 2
B10: 46029.581 | C10: 46204.583 | D10: anónimo | F10: 46204 | G10: 30/06/2026 | H10: DEYANIRA CORDOVA C/C | I10: MARIO | K10: MEHM641116HCLNRR04 | L10: 22125834 | M10: 8445409780 | N10: NUEVO MAYOR | O10: 9081.52 | Q10: 2724.46 | R10: 2724.46 | X10: 1
B11: 46029.586 | C11: 46204.588 | D11: anónimo | F11: 46204 | G11: 30/06/2026 | H11: ANA VILLEGAS C/C | I11: Fernando madera | J11: 1735247338 | L11: 22125778 | M11: 5214931259332 | N11: NUEVO MAYOR | O11: 23893.01 | Q11: 7167.9 | R11: 7167.9 | X11: 1
B12: 46029.59 | C12: 46204.591 | D12: anónimo | F12: 46204 | G12: 30/06/2026 | H12: ANA VILLEGAS C/C | I12: José Juan Félix | J12: 23846009217 | L12: 22128306 | M12: 5216871965719 | N12: NUEVO MENOR | O12: 26507.99 | P12: 6796.9 | Q12: 7952.4 | R12: 1155.5 | S12: 46398 | X12: 2
B13: 46029.601 | C13: 46204.603 | D13: anónimo | F13: 46204 | G13: 46029 | H13: IRAN CASTILLO SUR | I13: JOSE ANGEL LOPEZ CASAS | K13: LXCA621017HNLPSN09 | L13: 22162412 | M13: 5214881170727 | N13: COMPRA MAYOR | O13: 9081.52 | P13: 2518.66 | Q13: 2724.46 | R13: 205.8 | S13: 46029 | X13: 2
B14: 46029.607 | C14: 46204.61 | D14: anónimo | F14: 46204 | G14: 30/06/2026 | H14: DEYANIRA CORDOVA C/C | J14: 33806434180 | L14: 22126200 | M14: 6391558331 | N14: COMPRA MAYOR | O14: 18771.99 | P14: 5333.7 | Q14: 5631.6 | R14: 297.9 | S14: 46029 | X14: 2
B15: 46029.612 | C15: 46204.615 | D15: anónimo | F15: 46204 | G15: 30/06/2026 | H15: MARIA MARTINEZ SUR | I15: BEATRIZ HERNANDEZ RODRIGUEZ | J15: 60836000467 | K15: HERB600202MDFRDT00 | L15: 22151900 | M15: 5215578381289 | N15: COMPRA MENOR | O15: 5617.63 | P15: 1392.9 | Q15: 1685.29 | R15: 51.75 | S15: 46027 | X15: 2
B16: 46029.635 | C16: 46204.637 | D16: anónimo | F16: 46204 | G16: 46362 | H16: MARIA MARTINEZ SUR | I16: JULIO BASULTO USCANGA | K16: BAUJ630925HVZSSL04 | L16: 21661676 | M16: 5212971061427 | N16: COMPRA MAYOR | O16: 9081.52 | P16: 2500 | Q16: 2724.46 | R16: 224.46 | S16: 46029 | X16: 2
B17: 46029.519 | C17: 46204.647 | D17: anónimo | F17: 46204 | G17: 46029 | H17: MIRIAM MONTELONGO SUR | I17: JOSE DE JESUS MENDOZA GODINEZ | J17: 54795203865 | K17: MEGJ521109HJCNDS00 | L17: 22153278 | M17: 22153278 | N17: COMPRA MAYOR | O17: 9120.5 | P17: 2241 | Q17: 2736.15 | R17: 495.15 | S17: 45301 | X17: 2
B18: 46029.646 | C18: 46204.647 | D18: anónimo | F18: 46204 | G18: 46029 | H18: LUIS DAVILA C/C | J18: 54836503653 | K18: FOAD650805HJCLVV08 | L18: 22150440 | M18: 13344602961 | N18: NUEVO MENOR | O18: 9760.32 | P18: 2237.06 | Q18: 2928.1 | R18: 691.04 | S18: 46759 | X18: 2
B19: 46029.494 | C19: 46204.653 | D19: anónimo | F19: 46204 | G19: 24/06/2026 | H19: MARA HERNANDEZ SUR | I19: Marco Antonio Pacheco Castro | K19: PACM630406HMCCSR07 | L19: 21965960 | M19: 5215615423449 | N19: NUEVO MAYOR | O19: 9760.32 | P19: 879 | Q19: 2928.1 | R19: 2049.1 | X19: 1
B20: 46029.661 | C20: 46204.663 | D20: anónimo | F20: 46204 | G20: 46029 | H20: DULCE ARTEAGA SUR | I20: RAFAELA HERNANDEZ GARCIA | K20: HEGR620805MNLRRF07 | L20: 22160340 | M20: 5219601353463 | N20: COMPRA MAYOR | O20: 7116.73 | P20: 1972.32 | Q20: 2135.02 | R20: 162.7 | S20: 46024 | X20: 2
B21: 46029.665 | C21: 46204.672 | D21: anónimo | F21: 46204 | G21: 46029 | H21: JENNIFER AVENDAÑO SUR | I21: MARIA JULIETA PUENTE DEGOLLADO | J21: 43715531471 | K21: PUDJ680730MNLNGL02 | L21: 22173260 | M21: 5218117824579 | N21: NUEVO MENOR | O21: 5242.94 | Q21: 1572.88 | R21: 1069.96 | X21: 1
B22: 46029.724 | C22: 46204.726 | D22: anónimo | F22: 46204 | G22: 46029 | H22: MIRIAM MONTELONGO SUR | I22: MARIA GUADALUPE CRUZ DIAZ | K22: CUDG631113MSLRZD08 | L22: 22206188 | M22: 5216863525035 | N22: NUEVO MAYOR | O22: 9081.52 | P22: 879 | Q22: 2724.46 | R22: 1845.46 | X22: 1
B23: 46029.541 | C23: 46204.735 | D23: anónimo | F23: 46204 | G23: 46029 | H23: ESMERALDA ESQUIVEL SUR | I23: Antonio Olguin Rodriguez | J23: 3279622476 | K23: OURA621211HCLLDN00 | L23: 22206374 | M23: 5218661509862 | N23: COMPRA MAYOR | O23: 8539.89 | P23: 2306.32 | Q23: 2561.97 | R23: 255.65 | S23: 46023 | X23: 2
B24: 46060.42 | C24: 46205.424 | D24: anónimo | F24: 46205 | G24: 46029 | H24: JENNIFER AVENDAÑO SUR | I24: LUIS MANUEL CORTES SANCHEZ | J24: 54755612741 | K24: COSL560315HJCRNS04 | L24: 22175236 | M24: 5213411176544 | N24: NUEVO MAYOR | O24: 10636.54 | Q24: 3190.96 | R24: 3190.96 | X24: 1
B25: 46060.425 | C25: 46205.436 | D25: anónimo | F25: 46205 | G25: 46060 | H25: MAFER Z | I25: JUANA ROSARIO ZÚÑIGA VALLE | J25: 49876015642 | K25: ZUVJ600726MTSXLN00 | L25: 22227740 | M25: 528334484233 | N25: COMPRA MENOR | O25: 24606.78 | P25: 7379.13 | Q25: 7382.03 | R25: 2.9 | S25: 46026 | X25: 2
B26: 46060.481 | C26: 46205.481 | D26: anónimo | F26: 46205 | G26: 46060 | H26: YULIANA RODRIGUEZ C/C | I26: DANIEL CORREA ARCE | J26: 6785803617 | L26: 22241220 | M26: 5214421328128 | N26: NUEVO MAYOR | O26: 22109.54 | Q26: 6632.86 | R26: 6632.86 | X26: 1
B27: 46060.483 | C27: 46205.486 | D27: anónimo | F27: 46205 | G27: 46029 | H27: VALERY RODRIGUEZ SUR | I27: PEDRO ROJAS ALVAREZ | K27: ROAP620109HDFJLD04 | L27: 22176092 | M27: 5215629626816 | N27: NUEVO MAYOR | O27: 9081.52 | Q27: 2724.46 | R27: 2724.46 | X27: 1
B28: 46060.517 | C28: 46205.519 | D28: anónimo | F28: 46205 | G28: 46301 | H28: DEYANIRA CORDOVA C/C | I28: BLANCA | K28: MOCB660326MCMNML05 | L28: 21581006 | M28: 17208778718 | N28: NUEVO MAYOR | O28: 10636.54 | Q28: 3190.96 | R28: 3190.96 | X28: 1
B29: 46060.543 | C29: 46205.544 | D29: anónimo | F29: 46205 | G29: 46088 | H29: DEYANIRA CORDOVA C/C | I29: Alfredo Zavala | K29: ZATA620612HTSVDL03 | L29: 22242964 | M29: 5218683945967 | N29: COMPRA MAYOR | O29: 7920.51 | P29: 2182.22 | Q29: 2376.15 | R29: 193.93 | S29: 46027 | X29: 2
B30: 46060.553 | C30: 46205.554 | D30: anónimo | F30: 46205 | G30: 46060 | H30: HANIA GARCIA | I30: Francisco Guadarrama Valdes | K30: GUVF610405HDFDLR02 | L30: 22222084 | M30: 2969617653 | N30: NUEVO MAYOR | O30: 11444.12 | P30: 848 | Q30: 3433.24 | R30: 2585.24 | X30: 1
B31: 46060.562 | C31: 46205.563 | D31: anónimo | F31: 46205 | G31: 46060 | H31: DEYANIRA CORDOVA C/C | I31: Hector | K31: CORH760520HPLYMC02 | L31: 22243126 | M31: 5214614210356 | N31: NUEVO MENOR | O31: 4851.55 | Q31: 1455.47 | R31: 678.57 | X31: 1
B32: 46060.554 | C32: 46205.569 | D32: anónimo | F32: 46205 | G32: 46060 | H32: HANIA GARCIA | I32: Javier Espinoza Neira | K32: EINJ650713HCLSRV07 | L32: 22242138 | M32: 8446653191 | N32: NUEVO MENOR | O32: 12245.79 | P32: 3223.55 | Q32: 3673.74 | R32: 450.19 | X32: 1
B33: 46060.495 | C33: 46205.578 | D33: anónimo | F33: 46205 | G33: 46060 | H33: YULIANA RODRIGUEZ C/C | I33: martin gonzalez capitan | K33: GOCM591015HOCNPR05 | L33: 22242258 | M33: 5212871460110 | N33: NUEVO MAYOR | O33: 6099.07 | Q33: 1829.72 | R33: 1829.72 | X33: 1
B34: 46060.592 | C34: 46205.594 | D34: anónimo | F34: 46205 | G34: 46060 | H34: ALBERTO POZOS EXT | I34: JUAN CARLOS | J34: 60897104687 | L34: 1 | M34: 8715683390 | N34: RESTRINGIDA | O34: 8527.41 | P34: 1540.38 | Q34: 2558.22 | R34: 1017.84 | S34: 46029 | T34: FISOFO | X34: 2
B35: 46060.593 | C35: 46205.617 | D35: anónimo | F35: 46205 | G35: 46060 | H35: YAMILETH LÓPEZ HDEZ SUR | I35: ISMAEL PEREZ MORA | K35: PEMI631217HTSRRS03 | L35: 22245584 | M35: 5218125912554 | N35: NUEVO MAYOR | O35: 9504.7 | Q35: 2851.41 | R35: 2851.41 | X35: 1
B36: 46060.647 | C36: 46205.649 | D36: anónimo | F36: 46205 | G36: 46060 | H36: MARA HERNANDEZ SUR | I36: JUAN VARGAS MAYORGA | J36: 54886423372 | K36: VAMJ640821HNTRYN16 | L36: 22245440 | M36: 5213228889443 | N36: NUEVO MAYOR | O36: 10636.54 | Q36: 3190.96 | R36: 3190.96 | X36: 1
B37: 46060.63 | C37: 46205.683 | D37: anónimo | F37: 46205 | G37: 46060 | H37: HANIA GARCIA | I37: Juventino Martinez Silva | K37: MASJ530125HDFRLV03 | L37: 22245776 | M37: 5510173067 | N37: NUEVO MENOR | O37: 15842.31 | P37: 4342.05 | Q37: 4752.69 | R37: 410.64 | S37: 46032 | X37: 2
B38: 46060.7 | C38: 46205.701 | D38: anónimo | F38: 46205 | G38: 29/06/2026 | H38: FERNANDA ROMERO SUR | I38: GLORIA RUIZ SOTO | K38: RUSG650417MDFZTL09 | L38: 22099872 | M38: 5215534890206 | N38: COMPRA MENOR | O38: 5617.63 | P38: 1392.57 | Q38: 1685.29 | R38: 52.08 | S38: 45668 | X38: 2
B39: 46060.592 | C39: 46205.712 | D39: anónimo | F39: 46205 | G39: 46060 | H39: ROSA CASTRO SUR | I39: SONIA ZARATE PAZ | J39: 31907036086 | K39: ZAPS721109MMCRZN08 | L39: 22249500 | M39: 5216181582484 | N39: NUEVO MAYOR | O39: 8784.29 | Q39: 2635.29 | R39: 2635.29 | X39: 1
B40: 46060.737 | C40: 46205.738 | D40: anónimo | F40: 46205 | G40: 46060 | H40: ALBERTO POZOS EXT | J40: 31816321702 | L40: 1 | M40: NO PROMOCIONO | N40: NUEVO MENOR | O40: 7920.51 | P40: 1228.47 | Q40: 2376.15 | R40: 1147.68 | S40: 46394 | X40: 2
...

Sheet LISTA
A1: NUEVO MAYOR
A2: NO DATO
A3: COMPRA BIMESTRES
A4: COMPRA MAYOR
A5: NUEVO MENOR
A6: SIN CAPACIDAD
A7: RESTRINGIDA
A8: COMPRA MENOR
A9: LEY 97
A10: SIN NOMINA
A11: NEGOCIO DUPLICADO
A12: P.V.

Sheet REPORT YAMI
A1: PAGO POR SOLICITUD — CONTEO DE ESTATUS POR ASESORA
A2: Los filtros (periodo, tarifa y asesoras) se definen en la hoja SELECCIÓN. Esta hoja solo muestra resultados.
A3: ="Periodo: "&TEXT('SELECCIÓN YAMI'!$B$4,"dd/mm/yyyy")&" al "&TEXT('SELECCIÓN YAMI'!$B$6,"dd/mm/yyyy")&" — Tarifa: "&TEXT('SELECCIÓN YAMI'!$B$7,"$#,##0.00")&" — Asesoras: "&IF(COUNTIF('SELECCIÓN YAMI'!$B$14:$B$81,"X")=0,"TODAS las del periodo",COUNTIF('SELECCIÓN YAMI'!$B$14:$B$81,"X")&" marcadas en SELECCIÓN") -> Periodo: 30/07/2026 al 05/08/2026 — Tarifa: $10.00 — Asesoras: 3 marcadas en SELECCIÓN
A4: ASESORA | B4: NUEVO MAYOR | C4: COMPRA BIMESTRES | D4: COMPRA MAYOR | E4: NUEVO MENOR | F4: SIN CAPACIDAD | G4: RESTRINGIDA | H4: COMPRA MENOR | I4: SIN NOMINA | J4: TOTAL PAGABLE | K4: PAGO ($) | L4: NEGOCIO DUPLICADO | M4: NO DATO | N4: LEY 97 | O4: TOTAL SOLICITUDES
A5: TOTALES | B5: =SUM(B6:B72) -> 33 | C5: =SUM(C6:C72) -> 64 | D5: =SUM(D6:D72) -> 5 | E5: =SUM(E6:E72) -> 12 | F5: =SUM(F6:F72) -> 22 | G5: =SUM(G6:G72) -> 5 | H5: =SUM(H6:H72) -> 9 | I5: =SUM(I6:I72) -> 0 | ... O5: =SUM(O6:O72) -> 159
A6: {=IFERROR(_xlfn._xlws.FILTER('SELECCIÓN YAMI'!$A$14:$A$81,('SELECCIÓN YAMI'!$A$14:$A$81<>"")*((COUNTIF('SELECCIÓN YAMI'!$B$14:$B$81,"X")=0)+('SELECCIÓN YAMI'!$B$14:$B$81="X"))),"Sin resultados")} -> GIOVANNI MELGAR | B6: =IF($A6="","",COUNTIFS(Sheet1!$H$2:$H$5214,$A6,Sheet1!$N$2:$N$5214,B$4,Sheet1!$F$2:$F$5214,">="&'SELECCIÓN YAMI'!$B$4,Sheet1!$F$2:$F$5214,"<="&'SELECCIÓN YAMI'!$B$6)) -> 10 | C6: =IF($A6="","",COUNTIFS(Sheet1!$H$2:$H$5214,$A6,Sheet1!$N$2:$N$5214,C$4,Sheet1!$F$2:$F$5214,">="&'SELECCIÓN YAMI'!$B$4,Sheet1!$F$2:$F$5214,"<="&'SELECCIÓN YAMI'!$B$6)) -> 27 | D6: =IF($A6="","",COUNTIFS(Sheet1!$H$2:$H$5214,$A6,Sheet1!$N$2:$N$5214,D$4,Sheet1!$F$2:$F$5214,">="&'SELECCIÓN YAMI'!$B$4,Sheet1!$F$2:$F$5214,"<="&'SELECCIÓN YAMI'!$B$6)) -> 3 | E6: =IF($A6="","",COUNTIFS(Sheet1!$H$2:$H$5214,$A6,Sheet1!$N$2:$N$5214,E$4,Sheet1!$F$2:$F$5214,">="&'SELECCIÓN YAMI'!$B$4,Sheet1!$F$2:$F$5214,"<="&'SELECCIÓN YAMI'!$B$6)) -> 5 | F6: =IF($A6="","",COUNTIFS(Sheet1!$H$2:$H$5214,$A6,Sheet1!$N$2:$N$5214,F$4,Sheet1!$F$2:$F$5214,">="&'SELECCIÓN YAMI'!$B$4,Sheet1!$F$2:$F$5214,"<="&'SELECCIÓN YAMI'!$B$6)) -> 5 | G6: =IF($A6="","",COUNTIFS(Sheet1!$H$2:$H$5214,$A6,Sheet1!$N$2:$N$5214,G$4,Sheet1!$F$2:$F$5214,">="&'SELECCIÓN YAMI'!$B$4,Sheet1!$F$2:$F$5214,"<="&'SELECCIÓN YAMI'!$B$6)) -> 1 | H6: =IF($A6="","",COUNTIFS(Sheet1!$H$2:$H$5214,$A6,Sheet1!$N$2:$N$5214,H$4,Sheet1!$F$2:$F$5214,">="&'SELECCIÓN YAMI'!$B$4,Sheet1!$F$2:$F$5214,"<="&'SELECCIÓN YAMI'!$B$6)) -> 3 | I6: =IF($A6="","",COUNTIFS(Sheet1!$H$2:$H$5214,$A6,Sheet1!$N$2:$N$5214,I$4,Sheet1!$F$2:$F$5214,">="&'SELECCIÓN YAMI'!$B$4,Sheet1!$F$2:$F$5214,"<="&'SELECCIÓN YAMI'!$B$6)) -> 0 | J6: =IF($A6="","",SUM(B6:I6)) -> 54 | K6: =IF($A6="","",J6*'SELECCIÓN YAMI'!$B$7) -> 540 | L6: =IF($A6="","",COUNTIFS(Sheet1!$H$2:$H$5214,$A6,Sheet1!$N$2:$N$5214,L$4,Sheet1!$F$2:$F$5214,">="&'SELECCIÓN YAMI'!$B$4,Sheet1!$F$2:$F$5214,"<="&'SELECCIÓN YAMI'!$B$6)) -> 0 | M6: =IF($A6="","",COUNTIFS(Sheet1!$H$2:$H$5214,$A6,Sheet1!$N$2:$N$5214,M$4,Sheet1!$F$2:$F$5214,">="&'SELECCIÓN YAMI'!$B$4,Sheet1!$F$2:$F$5214,"<="&'SELECCIÓN YAMI'!$B$6)) -> 5 | N6: =IF($A6="","",COUNTIFS(Sheet1!$H$2:$H$5214,$A6,Sheet1!$N$2:$N$5214,N$4,Sheet1!$F$2:$F$5214,">="&'SELECCIÓN YAMI'!$B$4,Sheet1!$F$2:$F$5214,"<="&'SELECCIÓN YAMI'!$B$6)) -> 1 | O6: =IF($A6="","",COUNTIFS(Sheet1!$H$2:$H$5214,$A6,Sheet1!$F$2:$F$5214,">="&'SELECCIÓN YAMI'!$B$4,Sheet1!$F$2:$F$5214,"<="&'SELECCIÓN YAMI'!$B$6)) -> 60
A7: LILIANA MARTINEZ SUR | B7: =IF($A7="","",COUNTIFS(Sheet1!$H$2:$H$5214,$A7,Sheet1!$N$2:$N$5214,B$4,Sheet1!$F$2:$F$5214,">="&'SELECCIÓN YAMI'!$B$4,Sheet1!$F$2:$F$5214,"<="&'SELECCIÓN YAMI'!$B$6)) -> 7 | C7: =IF($A7="","",COUNTIFS(Sheet1!$H$2:$H$5214,$A7,Sheet1!$N$2:$N$5214,C$4,Sheet1!$F$2:$F$5214,">="&'SELECCIÓN YAMI'!$B$4,Sheet1!$F$2:$F$5214,"<="&'SELECCIÓN YAMI'!$B$6)) -> 8 | D7: =IF($A7="","",COUNTIFS(Sheet1!$H$2:$H$5214,$A7,Sheet1!$N$2:$N$5214,D$4,Sheet1!$F$2:$F$5214,">="&'SELECCIÓN YAMI'!$B$4,Sheet1!$F$2:$F$5214,"<="&'SELECCIÓN YAMI'!$B$6)) -> 1 | E7: =IF($A7="","",COUNTIFS(Sheet1!$H$2:$H$5214,$A7,Sheet1!$N$2:$N$5214,E$4,Sheet1!$F$2:$F$5214,">="&'SELECCIÓN YAMI'!$B$4,Sheet1!$F$2:$F$5214,"<="&'SELECCIÓN YAMI'!$B$6)) -> 1 | F7: =IF($A7="","",COUNTIFS(Sheet1!$H$2:$H$5214,$A7,Sheet1!$N$2:$N$5214,F$4,Sheet1!$F$2:$F$5214,">="&'SELECCIÓN YAMI'!$B$4,Sheet1!$F$2:$F$5214,"<="&'SELECCIÓN YAMI'!$B$6)) -> 10 | G7: =IF($A7="","",COUNTIFS(Sheet1!$H$2:$H$5214,$A7,Sheet1!$N$2:$N$5214,G$4,Sheet1!$F$2:$F$5214,">="&'SELECCIÓN YAMI'!$B$4,Sheet1!$F$2:$F$5214,"<="&'SELECCIÓN YAMI'!$B$6)) -> 2 | H7: =IF($A7="","",COUNTIFS(Sheet1!$H$2:$H$5214,$A7,Sheet1!$N$2:$N$5214,H$4,Sheet1!$F$2:$F$5214,">="&'SELECCIÓN YAMI'!$B$4,Sheet1!$F$2:$F$5214,"<="&'SELECCIÓN YAMI'!$B$6)) -> 0 | I7: =IF($A7="","",COUNTIFS(Sheet1!$H$2:$H$5214,$A7,Sheet1!$N$2:$N$5214,I$4,Sheet1!$F$2:$F$5214,">="&'SELECCIÓN YAMI'!$B$4,Sheet1!$F$2:$F$5214,"<="&'SELECCIÓN YAMI'!$B$6)) -> 0 | J7: =IF($A7="","",SUM(B7:I7)) -> 29 | K7: =IF($A7="","",J7*'SELECCIÓN YAMI'!$B$7) -> 290 | L7: =IF($A7="","",COUNTIFS(Sheet1!$H$2:$H$5214,$A7,Sheet1!$N$2:$N$5214,L$4,Sheet1!$F$2:$F$5214,">="&'SELECCIÓN YAMI'!$B$4,Sheet1!$F$2:$F$5214,"<="&'SELECCIÓN YAMI'!$B$6)) -> 0 | M7: =IF($A7="","",COUNTIFS(Sheet1!$H$2:$H$5214,$A7,Sheet1!$N$2:$N$5214,M$4,Sheet1!$F$2:$F$5214,">="&'SELECCIÓN YAMI'!$B$4,Sheet1!$F$2:$F$5214,"<="&'SELECCIÓN YAMI'!$B$6)) -> 1 | N7: =IF($A7="","",COUNTIFS(Sheet1!$H$2:$H$5214,$A7,Sheet1!$N$2:$N$5214,N$4,Sheet1!$F$2:$F$5214,">="&'SELECCIÓN YAMI'!$B$4,Sheet1!$F$2:$F$5214,"<="&'SELECCIÓN YAMI'!$B$6)) -> 0 | O7: =IF($A7="","",COUNTIFS(Sheet1!$H$2:$H$5214,$A7,Sheet1!$F$2:$F$5214,">="&'SELECCIÓN YAMI'!$B$4,Sheet1!$F$2:$F$5214,"<="&'SELECCIÓN YAMI'!$B$6)) -> 30
A8: ROSA CASTRO SUR | B8: =IF($A8="","",COUNTIFS(Sheet1!$H$2:$H$5214,$A8,Sheet1!$N$2:$N$5214,B$4,Sheet1!$F$2:$F$5214,">="&'SELECCIÓN YAMI'!$B$4,Sheet1!$F$2:$F$5214,"<="&'SELECCIÓN YAMI'!$B$6)) -> 16 | C8: =IF($A8="","",COUNTIFS(Sheet1!$H$2:$H$5214,$A8,Sheet1!$N$2:$N$5214,C$4,Sheet1!$F$2:$F$5214,">="&'SELECCIÓN YAMI'!$B$4,Sheet1!$F$2:$F$5214,"<="&'SELECCIÓN YAMI'!$B$6)) -> 29 | D8: =IF($A8="","",COUNTIFS(Sheet1!$H$2:$H$5214,$A8,Sheet1!$N$2:$N$5214,D$4,Sheet1!$F$2:$F$5214,">="&'SELECCIÓN YAMI'!$B$4,Sheet1!$F$2:$F$5214,"<="&'SELECCIÓN YAMI'!$B$6)) -> 1 | E8: =IF($A8="","",COUNTIFS(Sheet1!$H$2:$H$5214,$A8,Sheet1!$N$2:$N$5214,E$4,Sheet1!$F$2:$F$5214,">="&'SELECCIÓN YAMI'!$B$4,Sheet1!$F$2:$F$5214,"<="&'SELECCIÓN YAMI'!$B$6)) -> 6 | F8: =IF($A8="","",COUNTIFS(Sheet1!$H$2:$H$5214,$A8,Sheet1!$N$2:$N$5214,F$4,Sheet1!$F$2:$F$5214,">="&'SELECCIÓN YAMI'!$B$4,Sheet1!$F$2:$F$5214,"<="&'SELECCIÓN YAMI'!$B$6)) -> 7 | G8: =IF($A8="","",COUNTIFS(Sheet1!$H$2:$H$5214,$A8,Sheet1!$N$2:$N$5214,G$4,Sheet1!$F$2:$F$5214,">="&'SELECCIÓN YAMI'!$B$4,Sheet1!$F$2:$F$5214,"<="&'SELECCIÓN YAMI'!$B$6)) -> 2 | H8: =IF($A8="","",COUNTIFS(Sheet1!$H$2:$H$5214,$A8,Sheet1!$N$2:$N$5214,H$4,Sheet1!$F$2:$F$5214,">="&'SELECCIÓN YAMI'!$B$4,Sheet1!$F$2:$F$5214,"<="&'SELECCIÓN YAMI'!$B$6)) -> 6 | I8: =IF($A8="","",COUNTIFS(Sheet1!$H$2:$H$5214,$A8,Sheet1!$N$2:$N$5214,I$4,Sheet1!$F$2:$F$5214,">="&'SELECCIÓN YAMI'!$B$4,Sheet1!$F$2:$F$5214,"<="&'SELECCIÓN YAMI'!$B$6)) -> 0 | J8: =IF($A8="","",SUM(B8:I8)) -> 67 | K8: =IF($A8="","",J8*'SELECCIÓN YAMI'!$B$7) -> 670 | L8: =IF($A8="","",COUNTIFS(Sheet1!$H$2:$H$5214,$A8,Sheet1!$N$2:$N$5214,L$4,Sheet1!$F$2:$F$5214,">="&'SELECCIÓN YAMI'!$B$4,Sheet1!$F$2:$F$5214,"<="&'SELECCIÓN YAMI'!$B$6)) -> 0 | M8: =IF($A8="","",COUNTIFS(Sheet1!$H$2:$H$5214,$A8,Sheet1!$N$2:$N$5214,M$4,Sheet1!$F$2:$F$5214,">="&'SELECCIÓN YAMI'!$B$4,Sheet1!$F$2:$F$5214,"<="&'SELECCIÓN YAMI'!$B$6)) -> 2 | N8: =IF($A8="","",COUNTIFS(Sheet1!$H$2:$H$5214,$A8,Sheet1!$N$2:$N$5214,N$4,Sheet1!$F$2:$F$5214,">="&'SELECCIÓN YAMI'!$B$4,Sheet1!$F$2:$F$5214,"<="&'SELECCIÓN YAMI'!$B$6)) -> 0 | O8: =IF($A8="","",COUNTIFS(Sheet1!$H$2:$H$5214,$A8,Sheet1!$F$2:$F$5214,">="&'SELECCIÓN YAMI'!$B$4,Sheet1!$F$2:$F$5214,"<="&'SELECCIÓN YAMI'!$B$6)) -> 69
B9: =IF($A9="","",COUNTIFS(Sheet1!$H$2:$H$5214,$A9,Sheet1!$N$2:$N$5214,B$4,Sheet1!$F$2:$F$5214,">="&'SELECCIÓN YAMI'!$B$4,Sheet1!$F$2:$F$5214,"<="&'SELECCIÓN YAMI'!$B$6)) | C9: =IF($A9="","",COUNTIFS(Sheet1!$H$2:$H$5214,$A9,Sheet1!$N$2:$N$5214,C$4,Sheet1!$F$2:$F$5214,">="&'SELECCIÓN YAMI'!$B$4,Sheet1!$F$2:$F$5214,"<="&'SELECCIÓN YAMI'!$B$6)) | D9: =IF($A9="","",COUNTIFS(Sheet1!$H$2:$H$5214,$A9,Sheet1!$N$2:$N$5214,D$4,Sheet1!$F$2:$F$5214,">="&'SELECCIÓN YAMI'!$B$4,Sheet1!$F$2:$F$5214,"<="&'SELECCIÓN YAMI'!$B$6)) | E9: =IF($A9="","",COUNTIFS(Sheet1!$H$2:$H$5214,$A9,Sheet1!$N$2:$N$5214,E$4,Sheet1!$F$2:$F$5214,">="&'SELECCIÓN YAMI'!$B$4,Sheet1!$F$2:$F$5214,"<="&'SELECCIÓN YAMI'!$B$6)) | F9: =IF($A9="","",COUNTIFS(Sheet1!$H$2:$H$5214,$A9,Sheet1!$N$2:$N$5214,F$4,Sheet1!$F$2:$F$5214,">="&'SELECCIÓN YAMI'!$B$4,Sheet1!$F$2:$F$5214,"<="&'SELECCIÓN YAMI'!$B$6)) | G9: =IF($A9="","",COUNTIFS(Sheet1!$H$2:$H$5214,$A9,Sheet1!$N$2:$N$5214,G$4,Sheet1!$F$2:$F$5214,">="&'SELECCIÓN YAMI'!$B$4,Sheet1!$F$2:$F$5214,"<="&'SELECCIÓN YAMI'!$B$6)) | H9: =IF($A9="","",COUNTIFS(Sheet1!$H$2:$H$5214,$A9,Sheet1!$N$2:$N$5214,H$4,Sheet1!$F$2:$F$5214,">="&'SELECCIÓN YAMI'!$B$4,Sheet1!$F$2:$F$5214,"<="&'SELECCIÓN YAMI'!$B$6)) | I9: =IF($A9="","",COUNTIFS(Sheet1!$H$2:$H$5214,$A9,Sheet1!$N$2:$N$5214,I$4,Sheet1!$F$2:$F$5214,">="&'SELECCIÓN YAMI'!$B$4,Sheet1!$F$2:$F$5214,"<="&'SELECCIÓN YAMI'!$B$6)) | J9: =IF($A9="","",SUM(B9:I9)) | K9: =IF($A9="","",J9*'SELECCIÓN YAMI'!$B$7) | L9: =IF($A9="","",COUNTIFS(Sheet1!$H$2:$H$5214,$A9,Sheet1!$N$2:$N$5214,L$4,Sheet1!$F$2:$F$5214,">="&'SELECCIÓN YAMI'!$B$4,Sheet1!$F$2:$F$5214,"<="&'SELECCIÓN YAMI'!$B$6)) | M9: =IF($A9="","",COUNTIFS(Sheet1!$H$2:$H$5214,$A9,Sheet1!$N$2:$N$5214,M$4,Sheet1!$F$2:$F$5214,">="&'SELECCIÓN YAMI'!$B$4,Sheet1!$F$2:$F$5214,"<="&'SELECCIÓN YAMI'!$B$6)) | N9: =IF($A9="","",COUNTIFS(Sheet1!$H$2:$H$5214,$A9,Sheet1!$N$2:$N$5214,N$4,Sheet1!$F$2:$F$5214,">="&'SELECCIÓN YAMI'!$B$4,Sheet1!$F$2:$F$5214,"<="&'SELECCIÓN YAMI'!$B$6)) | O9: =IF($A9="","",COUNTIFS(Sheet1!$H$2:$H$5214,$A9,Sheet1!$F$2:$F$5214,">="&'SELECCIÓN YAMI'!$B$4,Sheet1!$F$2:$F$5214,"<="&'SELECCIÓN YAMI'!$B$6))
B10: =IF($A10="","",COUNTIFS(Sheet1!$H$2:$H$5214,$A10,Sheet1!$N$2:$N$5214,B$4,Sheet1!$F$2:$F$5214,">="&'SELECCIÓN YAMI'!$B$4,Sheet1!$F$2:$F$5214,"<="&'SELECCIÓN YAMI'!$B$6)) | C10: =IF($A10="","",COUNTIFS(Sheet1!$H$2:$H$5214,$A10,Sheet1!$N$2:$N$5214,C$4,Sheet1!$F$2:$F$5214,">="&'SELECCIÓN YAMI'!$B$4,Sheet1!$F$2:$F$5214,"<="&'SELECCIÓN YAMI'!$B$6)) | D10: =IF($A10="","",COUNTIFS(Sheet1!$H$2:$H$5214,$A10,Sheet1!$N$2:$N$5214,D$4,Sheet1!$F$2:$F$5214,">="&'SELECCIÓN YAMI'!$B$4,Sheet1!$F$2:$F$5214,"<="&'SELECCIÓN YAMI'!$B$6)) | E10: =IF($A10="","",COUNTIFS(Sheet1!$H$2:$H$5214,$A10,Sheet1!$N$2:$N$5214,E$4,Sheet1!$F$2:$F$5214,">="&'SELECCIÓN YAMI'!$B$4,Sheet1!$F$2:$F$5214,"<="&'SELECCIÓN YAMI'!$B$6)) | F10: =IF($A10="","",COUNTIFS(Sheet1!$H$2:$H$5214,$A10,Sheet1!$N$2:$N$5214,F$4,Sheet1!$F$2:$F$5214,">="&'SELECCIÓN YAMI'!$B$4,Sheet1!$F$2:$F$5214,"<="&'SELECCIÓN YAMI'!$B$6)) | G10: =IF($A10="","",COUNTIFS(Sheet1!$H$2:$H$5214,$A10,Sheet1!$N$2:$N$5214,G$4,Sheet1!$F$2:$F$5214,">="&'SELECCIÓN YAMI'!$B$4,Sheet1!$F$2:$F$5214,"<="&'SELECCIÓN YAMI'!$B$6)) | H10: =IF($A10="","",COUNTIFS(Sheet1!$H$2:$H$5214,$A10,Sheet1!$N$2:$N$5214,H$4,Sheet1!$F$2:$F$5214,">="&'SELECCIÓN YAMI'!$B$4,Sheet1!$F$2:$F$5214,"<="&'SELECCIÓN YAMI'!$B$6)) | I10: =IF($A10="","",COUNTIFS(Sheet1!$H$2:$H$5214,$A10,Sheet1!$N$2:$N$5214,I$4,Sheet1!$F$2:$F$5214,">="&'SELECCIÓN YAMI'!$B$4,Sheet1!$F$2:$F$5214,"<="&'SELECCIÓN YAMI'!$B$6)) | J10: =IF($A10="","",SUM(B10:I10)) | K10: =IF($A10="","",J10*'SELECCIÓN YAMI'!$B$7) | L10: =IF($A10="","",COUNTIFS(Sheet1!$H$2:$H$5214,$A10,Sheet1!$N$2:$N$5214,L$4,Sheet1!$F$2:$F$5214,">="&'SELECCIÓN YAMI'!$B$4,Sheet1!$F$2:$F$5214,"<="&'SELECCIÓN YAMI'!$B$6)) | M10: =IF($A10="","",COUNTIFS(Sheet1!$H$2:$H$5214,$A10,Sheet1!$N$2:$N$5214,M$4,Sheet1!$F$2:$F$5214,">="&'SELECCIÓN YAMI'!$B$4,Sheet1!$F$2:$F$5214,"<="&'SELECCIÓN YAMI'!$B$6)) | N10: =IF($A10="","",COUNTIFS(Sheet1!$H$2:$H$5214,$A10,Sheet1!$N$2:$N$5214,N$4,Sheet1!$F$2:$F$5214,">="&'SELECCIÓN YAMI'!$B$4,Sheet1!$F$2:$F$5214,"<="&'SELECCIÓN YAMI'!$B$6)) | O10: =IF($A10="","",COUNTIFS(Sheet1!$H$2:$H$5214,$A10,Sheet1!$F$2:$F$5214,">="&'SELECCIÓN YAMI'!$B$4,Sheet1!$F$2:$F$5214,"<="&'SELECCIÓN YAMI'!$B$6))
B11: =IF($A11="","",COUNTIFS(Sheet1!$H$2:$H$5214,$A11,Sheet1!$N$2:$N$5214,B$4,Sheet1!$F$2:$F$5214,">="&'SELECCIÓN YAMI'!$B$4,Sheet1!$F$2:$F$5214,"<="&'SELECCIÓN YAMI'!$B$6)) | C11: =IF($A11="","",COUNTIFS(Sheet1!$H$2:$H$5214,$A11,Sheet1!$N$2:$N$5214,C$4,Sheet1!$F$2:$F$5214,">="&'SELECCIÓN YAMI'!$B$4,Sheet1!$F$2:$F$5214,"<="&'SELECCIÓN YAMI'!$B$6)) | D11: =IF($A11="","",COUNTIFS(Sheet1!$H$2:$H$5214,$A11,Sheet1!$N$2:$N$5214,D$4,Sheet1!$F$2:$F$5214,">="&'SELECCIÓN YAMI'!$B$4,Sheet1!$F$2:$F$5214,"<="&'SELECCIÓN YAMI'!$B$6)) | E11: =IF($A11="","",COUNTIFS(Sheet1!$H$2:$H$5214,$A11,Sheet1!$N$2:$N$5214,E$4,Sheet1!$F$2:$F$5214,">="&'SELECCIÓN YAMI'!$B$4,Sheet1!$F$2:$F$5214,"<="&'SELECCIÓN YAMI'!$B$6)) | F11: =IF($A11="","",COUNTIFS(Sheet1!$H$2:$H$5214,$A11,Sheet1!$N$2:$N$5214,F$4,Sheet1!$F$2:$F$5214,">="&'SELECCIÓN YAMI'!$B$4,Sheet1!$F$2:$F$5214,"<="&'SELECCIÓN YAMI'!$B$6)) | G11: =IF($A11="","",COUNTIFS(Sheet1!$H$2:$H$5214,$A11,Sheet1!$N$2:$N$5214,G$4,Sheet1!$F$2:$F$5214,">="&'SELECCIÓN YAMI'!$B$4,Sheet1!$F$2:$F$5214,"<="&'SELECCIÓN YAMI'!$B$6)) | H11: =IF($A11="","",COUNTIFS(Sheet1!$H$2:$H$5214,$A11,Sheet1!$N$2:$N$5214,H$4,Sheet1!$F$2:$F$5214,">="&'SELECCIÓN YAMI'!$B$4,Sheet1!$F$2:$F$5214,"<="&'SELECCIÓN YAMI'!$B$6)) | I11: =IF($A11="","",COUNTIFS(Sheet1!$H$2:$H$5214,$A11,Sheet1!$N$2:$N$5214,I$4,Sheet1!$F$2:$F$5214,">="&'SELECCIÓN YAMI'!$B$4,Sheet1!$F$2:$F$5214,"<="&'SELECCIÓN YAMI'!$B$6)) | J11: =IF($A11="","",SUM(B11:I11)) | K11: =IF($A11="","",J11*'SELECCIÓN YAMI'!$B$7) | L11: =IF($A11="","",COUNTIFS(Sheet1!$H$2:$H$5214,$A11,Sheet1!$N$2:$N$5214,L$4,Sheet1!$F$2:$F$5214,">="&'SELECCIÓN YAMI'!$B$4,Sheet1!$F$2:$F$5214,"<="&'SELECCIÓN YAMI'!$B$6)) | M11: =IF($A11="","",COUNTIFS(Sheet1!$H$2:$H$5214,$A11,Sheet1!$N$2:$N$5214,M$4,Sheet1!$F$2:$F$5214,">="&'SELECCIÓN YAMI'!$B$4,Sheet1!$F$2:$F$5214,"<="&'SELECCIÓN YAMI'!$B$6)) | N11: =IF($A11="","",COUNTIFS(Sheet1!$H$2:$H$5214,$A11,Sheet1!$N$2:$N$5214,N$4,Sheet1!$F$2:$F$5214,">="&'SELECCIÓN YAMI'!$B$4,Sheet1!$F$2:$F$5214,"<="&'SELECCIÓN YAMI'!$B$6)) | O11: =IF($A11="","",COUNTIFS(Sheet1!$H$2:$H$5214,$A11,Sheet1!$F$2:$F$5214,">="&'SELECCIÓN YAMI'!$B$4,Sheet1!$F$2:$F$5214,"<="&'SELECCIÓN YAMI'!$B$6))
