Workbook

Sheet Hoja1
A1: ID Lead | B1: fecha | C1: Hora | D1: Nombre | E1: Telefono | F1: telefono2 | G1: CURP | H1: NSS | I1: Fecha_de_nac | J1: Estado_de_nac | K1: ESTATUS | L1: INFORMEDEPAGO | M1: DESCUENTOS | N1: $0.30 | O1: CAPACIDAD | P1: VENCIMIENTO | Q1: FINANCIERA | R1: MONTO COMPRA | S1: ASIGNADO A | T1: FECHA ASIG | U1: Columna1 | V1: Columna2 | W1: Columna3 | X1: Columna4 | Y1: Columna5 | Z1: CONTEO PANTALLA
A2: 23298744 | B2: 46236 | C2: 0.59015046 | E2: 5218113173320 | G2: TORJ591111HNLRVN03 | H2: 43825908031 | K2: COMPRA MAYOR | L2: 46262.13 | M2: 13312.31 | N2: =L2*0.3 -> 13878.639 | O2: =(IF(L2<4172.98,0,MIN(L2*0.3,L2-4172.98)))-M2 -> 566.329 | P2: 46113 | S2: IRASEMA | T2: 46237 | Z2: 2
A3: 23299154 | B3: 46236 | C3: 0.61292824 | E3: 5218182058119 | G3: EUHA671126HVZSRN05 | H3: 67866773756 | K3: COMPRA BIMESTRES | L3: 10369.35 | M3: 2999.23 | N3: =L3*0.3 -> 3110.805 | O3: =(IF(L3<4172.98,0,MIN(L3*0.3,L3-4172.98)))-M3 -> 111.575 | P3: 46600 | S3: KARLA | Z3: 2
A4: 23299316 | B4: 46236 | C4: 0.62565972 | E4: 5215521391613 | H4: 30139412834 | K4: NO DATO | N4: =L4*0.3 -> 0 | O4: =(IF(L4<4172.98,0,MIN(L4*0.3,L4-4172.98)))-M4 -> 0 | S4: KARLA | Z4: 0
A5: 23299656 | B5: 46236 | C5: 0.64082176 | D5: JOSE MANUEL CASTRO PANTOJA | E5: 5219131072974 | H5: 81916820731 | K5: NO DATO | N5: =L5*0.3 -> 0 | O5: =(IF(L5<4172.98,0,MIN(L5*0.3,L5-4172.98)))-M5 -> 0 | S5: KARLA | Z5: 0
A6: 23299908 | B6: 46236 | C6: 0.65543981 | E6: 5215519497280 | H6: 40856200429 | K6: COMPRA BIMESTRES | L6: 8422.91 | M6: 2405.4 | N6: =L6*0.3 -> 2526.873 | O6: =(IF(L6<4172.98,0,MIN(L6*0.3,L6-4172.98)))-M6 -> 121.473 | P6: 46692 | S6: KARLA | Z6: 2
A7: 23299544 | B7: 46236 | C7: 0.66197917 | E7: 5218123566431 | H7: 43786040246 | K7: RESTRINGIDA | L7: 57317.73 | M7: 7395.9 | N7: =L7*0.3 -> 17195.319 | O7: =(IF(L7<4172.98,0,MIN(L7*0.3,L7-4172.98)))-M7 -> 9799.419 | P7: 45901 | S7: DANIELLY | T7: 46237 | Z7: 2
A8: 23300568 | B8: 46236 | C8: 0.68758102 | E8: 5218112130042 | H8: 0-3664819434 | K8: COMPRA BIMESTRES | L8: 5731.78 | M8: 1471.96 | N8: =L8*0.3 -> 1719.534 | O8: =(IF(L8<4172.98,0,MIN(L8*0.3,L8-4172.98)))-M8 -> 86.84 | P8: 46539 | S8: KARLA | Z8: 2
A9: 23300548 | B9: 46236 | C9: 0.69230324 | E9: 5219982196773 | G9: KACG691208HCCNHS09 | K9: NO DATO | N9: =L9*0.3 -> 0 | O9: =(IF(L9<4172.98,0,MIN(L9*0.3,L9-4172.98)))-M9 -> 0 | S9: KARLA | Z9: 0
A10: 23300600 | B10: 46236 | C10: 0.7021412 | E10: 5219515471777 | H10: 78715500605 | K10: NUEVO MENOR | L10: 31365.91 | M10: 8967.69 | N10: =L10*0.3 -> 9409.773 | O10: =(IF(L10<4172.98,0,MIN(L10*0.3,L10-4172.98)))-M10 -> 442.083 | P10: 46508 | Q10: RESTRINGIDA | S10: HECTOR | T10: 46237 | Z10: 2
A11: 23300818 | B11: 46236 | C11: 0.710625 | E11: 5216141849678 | G11: HEQT630204MCHRXR01 | H11: 11806300767 | K11: COMPRA BIMESTRES | L11: 33322.3 | M11: 9995.93 | N11: =L11*0.3 -> 9996.69 | O11: =(IF(L11<4172.98,0,MIN(L11*0.3,L11-4172.98)))-M11 -> 0.76 | P11: 46235 | Q11: profuturo | S11: KARLA | Z11: 2
A12: 23300914 | B12: 46236 | C12: 0.7128125 | E12: 5216141034612 | H12: 33956603576 | K12: NO DATO | N12: =L12*0.3 -> 0 | O12: =(IF(L12<4172.98,0,MIN(L12*0.3,L12-4172.98)))-M12 -> 0 | S12: KARLA | Z12: 0
A13: 23300954 | B13: 46236 | C13: 0.7149537 | E13: 5213322629652 | G13: COSI610201HGRRLG09 | H13: 1916102757 | K13: COMPRA BIMESTRES | L13: 11813.73 | M13: 3404.55 | N13: =L13*0.3 -> 3544.119 | O13: =(IF(L13<4172.98,0,MIN(L13*0.3,L13-4172.98)))-M13 -> 139.569 | P13: 46569 | Q13: CONSUPAGO | S13: KARLA | Z13: 2
A14: 23300706 | B14: 46236 | C14: 0.71751157 | E14: 5214492254213 | H14: 51816312808 | K14: COMPRA MAYOR | L14: 7920.51 | M14: 2198.96 | N14: =L14*0.3 -> 2376.153 | O14: =(IF(L14<4172.98,0,MIN(L14*0.3,L14-4172.98)))-M14 -> 177.193 | P14: 46143 | Q14: DIMEX | S14: IRASEMA | T14: 46237 | Z14: 2
A15: 23301076 | B15: 46236 | C15: 0.72693287 | E15: 5216241580631 | H15: 64806023236 | K15: NUEVO MENOR | L15: 6262.86 | M15: 848 | N15: =L15*0.3 -> 1878.858 | O15: =(IF(L15<4172.98,0,MIN(L15*0.3,L15-4172.98)))-M15 -> 1030.858 | S15: HECTOR | T15: 46237 | Z15: 1
A16: 23301050 | B16: 46236 | C16: 0.726875 | D16: MIGUEL ANGEL MEZA | E16: 5213121546335 | G16: MEXM510110HCMZXG02 | H16: 52725112495 | K16: COMPRA BIMESTRES | L16: 9387.46 | M16: 2605.38 | N16: =L16*0.3 -> 2816.238 | O16: =(IF(L16<4172.98,0,MIN(L16*0.3,L16-4172.98)))-M16 -> 210.858 | P16: 46235 | Q16: EXITUS | S16: KARLA | Z16: 2
A17: 23301084 | B17: 46236 | C17: 0.73387731 | E17: 5219511903730 | G17: vema420815HOCRRR00 | H17: 859420007 | K17: COMPRA BIMESTRES | L17: 20593.46 | M17: 6175.19 | N17: =L17*0.3 -> 6178.038 | O17: =(IF(L17<4172.98,0,MIN(L17*0.3,L17-4172.98)))-M17 -> 2.848 | P17: 46539 | Q17: EXITUS | S17: KARLA | Z17: 2
A18: 23300266 | B18: 46236 | C18: 0.73394676 | D18: MARIO GARCIA NITSCH | E18: 5219381573554 | G18: GANM991202HCSRTR01 | K18: LEY 97 | N18: =L18*0.3 -> 0 | O18: =(IF(L18<4172.98,0,MIN(L18*0.3,L18-4172.98)))-M18 -> 0 | S18: KARLA | Z18: 1
A19: 23301510 | B19: 46236 | C19: 0.75048611 | E19: 5212331346637 | G19: VAHN790421HPLLRX06 | K19: NO DATO | N19: =L19*0.3 -> 0 | O19: =(IF(L19<4172.98,0,MIN(L19*0.3,L19-4172.98)))-M19 -> 0 | S19: KARLA | Z19: 0
A20: 23301606 | B20: 46236 | C20: 0.75385417 | E20: 5215616651378 | G20: FOMM650802MVZRRR06 | H20: 88836524681 | K20: NUEVO MAYOR | L20: 9760.32 | N20: =L20*0.3 -> 2928.096 | O20: =(IF(L20<4172.98,0,MIN(L20*0.3,L20-4172.98)))-M20 -> 2928.096 | S20: ITZELH | T20: 46237 | Z20: 1
A21: 23300712 | B21: 46236 | C21: 0.77042824 | E21: 5218712079281 | G21: MACC660503HCLRRR06 | H21: 32836511389 | K21: COMPRA BIMESTRES | L21: 10636.54 | M21: 3190.96 | N21: =L21*0.3 -> 3190.962 | O21: =(IF(L21<4172.98,0,MIN(L21*0.3,L21-4172.98)))-M21 -> 0.002 | P21: 46935 | Q21: FISOFO | S21: KARLA | Z21: 2
A22: 23301156 | B22: 46236 | C22: 0.77510417 | E22: 5216223428578 | H22: 24887124378 | K22: SIN CAPACIDAD | L22: =2689.75+879 -> 3568.75 | M22: 879 | N22: =L22*0.3 -> 1070.625 | O22: =(IF(L22<4172.98,0,MIN(L22*0.3,L22-4172.98)))-M22 -> -879 | S22: KARLA | Z22: 1
A23: 23302060 | B23: 46236 | C23: 0.77675926 | E23: 5214423568355 | H23: 11795864781 | K23: COMPRA BIMESTRES | L23: 14510.86 | M23: 4198.34 | N23: =L23*0.3 -> 4353.258 | O23: =(IF(L23<4172.98,0,MIN(L23*0.3,L23-4172.98)))-M23 -> 154.918 | P23: 46266 | Q23: MULTIVA | S23: KARLA | Z23: 2
A24: 23301374 | B24: 46236 | C24: 0.81193287 | E24: 5213521444213 | G24: FOFT610912MMNNGR00 | K24: COMPRA BIMESTRES | L24: 11019.46 | M24: 3059.39 | N24: =L24*0.3 -> 3305.838 | O24: =(IF(L24<4172.98,0,MIN(L24*0.3,L24-4172.98)))-M24 -> 246.448 | P24: 46388 | S24: KARLA | Z24: 2
A25: 23301550 | B25: 46236 | C25: 0.82350694 | E25: 5218332313530 | H25: 33856811998 | K25: COMPRA BIMESTRES | L25: 8793.09 | M25: 2456.91 | N25: =L25*0.3 -> 2637.927 | O25: =(IF(L25<4172.98,0,MIN(L25*0.3,L25-4172.98)))-M25 -> 181.017 | P25: 46753 | S25: KARLA | Z25: 2
A26: 23303754 | B26: 46236 | C26: 0.8347338 | E26: 5214493217711 | G26: RASS550909HDFMNR09 | K26: COMPRA BIMESTRES | L26: 24326.77 | M26: 7037.95 | N26: =L26*0.3 -> 7298.031 | O26: =(IF(L26<4172.98,0,MIN(L26*0.3,L26-4172.98)))-M26 -> 260.081 | P26: 46419 | Q26: FISOFO | S26: KARLA | Z26: 2
A27: 23303760 | B27: 46236 | C27: 0.83721065 | E27: 5219622567303 | H27: 71886400559 | K27: NUEVO MAYOR | L27: 14465.36 | M27: 0 | N27: =L27*0.3 -> 4339.608 | O27: =(IF(L27<4172.98,0,MIN(L27*0.3,L27-4172.98)))-M27 -> 4339.608 | S27: CAROLINA | T27: 46237 | Z27: 1
A28: 23304336 | B28: 46236 | C28: 0.90251157 | E28: 5215561400218 | H28: 1785694611 | K28: NUEVO MAYOR | L28: 47739.84 | N28: =L28*0.3 -> 14321.952 | O28: =(IF(L28<4172.98,0,MIN(L28*0.3,L28-4172.98)))-M28 -> 14321.952 | S28: MELANIE | T28: 46237 | Z28: 1
A29: 23305526 | B29: 46236 | C29: 0.9447338 | D29: Dorotea Martha Cuevas Torres | E29: 5215519527420 | G29: CUTD560701DFVR02 | K29: NO DATO | N29: =L29*0.3 -> 0 | O29: =(IF(L29<4172.98,0,MIN(L29*0.3,L29-4172.98)))-M29 -> 0 | S29: KARLA | Z29: 0
A30: 23305844 | B30: 46237 | C30: 0.0077546296 | D30: Francisco | E30: 5214447676859 | H30: 43826501819 | K30: COMPRA BIMESTRES | L30: 9760.32 | M30: 2928.1 | N30: =L30*0.3 -> 2928.096 | O30: =(IF(L30<4172.98,0,MIN(L30*0.3,L30-4172.98)))-M30 -> -0.004 | P30: 46813 | S30: KARLA | Z30: 2
A31: 23306038 | B31: 46237 | C31: 0.050439815 | D31: ALFREDO AGUSTIN PEREZ DIAZ | E31: 5215521373260 | G31: PXDA560828HCSRZL07 | K31: COMPRA BIMESTRES | L31: 7116.73 | M31: 2058.29 | N31: =L31*0.3 -> 2135.019 | O31: =(IF(L31<4172.98,0,MIN(L31*0.3,L31-4172.98)))-M31 -> 76.729 | P31: 46508 | S31: MAFER | Z31: 2
A32: 23306394 | B32: 46237 | C32: 0.11071759 | E32: 5216862587212 | G32: MAEJ690216HBCRSS00 | K32: COMPRA BIMESTRES | L32: 5642.22 | M32: 1413.59 | N32: =L32*0.3 -> 1692.666 | O32: =(IF(L32<4172.98,0,MIN(L32*0.3,L32-4172.98)))-M32 -> 55.65 | P32: 46478 | S32: MAFER | Z32: 2
A33: 23306340 | B33: 46237 | C33: 0.11096065 | E33: 5218129262667 | G33: mabf611016hnlcrr01 | H33: 0379-61-0515 | K33: COMPRA BIMESTRES | L33: 7920.51 | M33: 2285.09 | N33: =L33*0.3 -> 2376.153 | O33: =(IF(L33<4172.98,0,MIN(L33*0.3,L33-4172.98)))-M33 -> 91.063 | P33: 46631 | Q33: OPCIPRES | S33: MAFER | Z33: 2
A34: 23306562 | B34: 46237 | C34: 0.15483796 | E34: 5214444036595 | G34: OEOA640821HSPJVN02 | H34: 41836417901 | K34: COMPRA BIMESTRES | L34: 18548.66 | M34: 5358.89 | N34: =L34*0.3 -> 5564.598 | O34: =(IF(L34<4172.98,0,MIN(L34*0.3,L34-4172.98)))-M34 -> 205.708 | P34: 46357 | Q34: INBURSA | S34: MAFER | Z34: 2
A35: 23308894 | B35: 46237 | C35: 0.27009259 | E35: 5219982902594 | G35: CAML650225HDFHLS08 | K35: COMPRA BIMESTRES | L35: 9760.32 | M35: 2823.87 | N35: =L35*0.3 -> 2928.096 | O35: =(IF(L35<4172.98,0,MIN(L35*0.3,L35-4172.98)))-M35 -> 104.226 | P35: 46539 | Q35: PROFUTURO | S35: MAFER | Z35: 2
A36: 23308282 | B36: 46237 | C36: 0.29179398 | E36: 5218110179950 | G36: Came601023HNLSRN00 | K36: SIN CAPACIDAD | L36: 3904.2 | N36: =L36*0.3 -> 1171.26 | O36: =(IF(L36<4172.98,0,MIN(L36*0.3,L36-4172.98)))-M36 -> 0 | S36: MAFER | Z36: 1
A37: 23310882 | B37: 46237 | C37: 0.32886574 | E37: 5215577134189 | H37: 1624802912 | K37: SIN CAPACIDAD | L37: =2119.01+706 -> 2825.01 | N37: =L37*0.3 -> 847.503 | O37: =(IF(L37<4172.98,0,MIN(L37*0.3,L37-4172.98)))-M37 -> 0 | S37: MAFER | Z37: 1
A38: 23311058 | B38: 46237 | C38: 0.33341435 | E38: 5219381005997 | G38: MEBS630912HVZNCM00 | H38: 81816307003 | K38: NUEVO MENOR | L38: 27974.31 | M38: 7719.91 | N38: =L38*0.3 -> 8392.293 | O38: =(IF(L38<4172.98,0,MIN(L38*0.3,L38-4172.98)))-M38 -> 672.383 | P38: 46388 | S38: HECTOR | T38: 46237 | Z38: 2
A39: 23311722 | B39: 46237 | C39: 0.35986111 | E39: 5214612511235 | H39: 32826478003 | K39: COMPRA BIMESTRES | L39: 9081.52 | M39: 2716.91 | N39: =L39*0.3 -> 2724.456 | O39: =(IF(L39<4172.98,0,MIN(L39*0.3,L39-4172.98)))-M39 -> 7.546 | P39: 46874 | S39: MAFER | Z39: 2
A40: 23312206 | B40: 46237 | C40: 0.36368056 | E40: 5219878783729 | H40: 82937323549 | K40: NUEVO MENOR | L40: 4746.87 | N40: =L40*0.3 -> 1424.061 | O40: =(IF(L40<4172.98,0,MIN(L40*0.3,L40-4172.98)))-M40 -> 573.89 | S40: HECTOR | T40: 46237 | Z40: 1
...

Sheet Etiquetas
A1: ASIGNADO A | B1: ETIQUETA REAL EN KOMMO
A2: ANA | B2: ANA VILLEGAS CIERRES
A3: ANDRE | B3: ANDRE TREVIÑO CIERRES
A4: CAROLINA | B4: CAROLINA RAMIREZ CIERRES
A5: DANIELLY | B5: DANIELLY RODRIGUEZ CIERRES
A6: DULCE | B6: DULCE FRANCO CIERRES
A7: EDNA | B7: EDNA RODRIGUEZ CIERRES
A8: FERNANDA | B8: FERNANDA CASTILLO CIERRES
A9: GABRIELA | B9: GABRIELA SANCHEZ CIERRES
A10: GLORIA | B10: GRLORIA ORTIZ CIERRES
A11: HANIA | B11: HANIA GARCIA CIERRES
A12: HECTOR | B12: HECTOR RODRIGUEZ CIERRES
... A22: PAOLA | B22: PAOLA RODRIGUEZ CIERRES

Sheet ACUMULADO NEGOCIOS
A1: ID Lead | B1: fecha | C1: Hora | D1: Nombre | E1: Telefono | F1: telefono2 | G1: CURP | H1: NSS | I1: Fecha_de_nac | J1: Estado_de_nac | K1: ESTATUS | L1: INFORMEDEPAGO | M1: DESCUENTOS | N1: $0.30 | O1: CAPACIDAD | P1: VENCIMIENTO | Q1: FINANCIERA | R1: MONTO COMPRA | S1: ASIGNADO A
A2: 24154706 | B2: 46266 | C2: 0.41545139 | E2: 5218184674241 | H2: 43866647795 | K2: NUEVO MAYOR | L2: 10636.54 | N2: =L2*0.3 -> 3190.962 | O2: =(IF(L2<4172.98,0,MIN(L2*0.3,L2-4172.98)))-M2 -> 3190.962 | S2: ITZELH
A3: 24155064 | B3: 46266 | C3: 0.41986111 | E3: 5218119766225 | H3: 43826405516 | K3: NUEVO MAYOR | L3: 38440.16 | N3: =L3*0.3 -> 11532.048 | O3: =(IF(L3<4172.98,0,MIN(L3*0.3,L3-4172.98)))-M3 -> 11532.048 | S3: MIRIAM
A4: 24155260 | B4: 46266 | C4: 0.42607639 | D4: JOSE LUIS HERNANDEZ GALVAN | E4: 5218448276340 | G4: HEGL630304HLCRLS06 | H4: 32806376532 | K4: COMPRA MAYOR | L4: 11545.07 | M4: 3205.32 | N4: =L4*0.3 -> 3463.521 | O4: =(IF(L4<4172.98,0,MIN(L4*0.3,L4-4172.98)))-M4 -> 258.201 | P4: 46266 | Q4: INBURSA | R4: 3205.32 | S4: IRASEMA
A5: 24155744 | B5: 46266 | C5: 0.44333333 | E5: 5218332187743 | H5: 4980560549-7 | K5: NUEVO MAYOR | L5: 52406.17 | N5: =L5*0.3 -> 15721.851 | O5: =(IF(L5<4172.98,0,MIN(L5*0.3,L5-4172.98)))-M5 -> 15721.851 | S5: MIRIAM
A6: 24156542 | B6: 46266 | C6: 0.46457176 | E6: 5213334444792 | G6: Saam630902mjcnnr06 | K6: NUEVO MAYOR | L6: =152780.53-127457.79 -> 25322.74 | N6: =L6*0.3 -> 7596.822 | O6: =(IF(L6<4172.98,0,MIN(L6*0.3,L6-4172.98)))-M6 -> 7596.822 | S6: ITZELH
A7: 24156688 | B7: 46266 | C7: 0.46983796 | E7: 5219841467459 | H7: 0675577155-4 | K7: NUEVO MENOR | L7: 5046.19 | N7: =L7*0.3 -> 1513.857 | O7: =(IF(L7<4172.98,0,MIN(L7*0.3,L7-4172.98)))-M7 -> 873.21 | S7: HANIA
A8: 24156958 | B8: 46266 | C8: 0.47414352 | E8: 5218111833089 | G8: MORF651003MNLRDL00 | K8: NUEVO MAYOR | L8: 10636.54 | N8: =L8*0.3 -> 3190.962 | O8: =(IF(L8<4172.98,0,MIN(L8*0.3,L8-4172.98)))-M8 -> 3190.962 | S8: ANA
A9: 24158638 | B9: 46266 | C9: 0.51876157 | D9: Guillermo Duran Lorenzo | E9: 5218110181156 | H9: 43735334849 | K9: NUEVO MENOR | L9: 31962.39 | M9: 8873.12 | N9: =L9*0.3 -> 9588.717 | O9: =(IF(L9<4172.98,0,MIN(L9*0.3,L9-4172.98)))-M9 -> 715.597 | P9: 46419 | Q9: MULTIVA | R9: 8873.12 | S9: HANIA
A10: 24159388 | B10: 46266 | C10: 0.53233796 | D10: José | E10: 5218445025706 | H10: 32816461415 | K10: NUEVO MAYOR | L10: 40832.2 | N10: =L10*0.3 -> 12249.66 | O10: =(IF(L10<4172.98,0,MIN(L10*0.3,L10-4172.98)))-M10 -> 12249.66 | S10: IRASEMA
A11: 24161368 | B11: 46266 | C11: 0.55391204 | E11: 5216644310392 | G11: MOLL640907HVZRBM04 | H11: 67834662357 | K11: NUEVO MAYOR | L11: 11029.03 | N11: =L11*0.3 -> 3308.709 | O11: =(IF(L11<4172.98,0,MIN(L11*0.3,L11-4172.98)))-M11 -> 3308.709 | S11: KARINA
A12: 24161588 | B12: 46266 | C12: 0.56670139 | E12: 5218113887928 | H12: 43 8060 08272 | K12: NUEVO MAYOR | L12: 30669.12 | M12: 3034.58 | N12: =L12*0.3 -> 9200.736 | O12: =(IF(L12<4172.98,0,MIN(L12*0.3,L12-4172.98)))-M12 -> 6166.156 | P12: 46600 | Q12: MULTIVA | R12: 3034.58 | S12: KARINA
A13: 24171110 | B13: 46266 | C13: 0.68592593 | E13: 5216391767613 | G13: GUCE561014MCHRHL04 | K13: NUEVO MAYOR | L13: 10483.8 | M13: 848 | N13: =L13*0.3 -> 3145.14 | O13: =(IF(L13<4172.98,0,MIN(L13*0.3,L13-4172.98)))-M13 -> 2297.14 | S13: MARISOL
A14: 24171284 | B14: 46266 | C14: 0.69449074 | E14: 5216741161016 | G14: SANC650218HDGRVR02 | K14: NUEVO MENOR | L14: 9760.32 | M14: =1651.54+735.36 -> 2386.9 | N14: =L14*0.3 -> 2928.096 | O14: =(IF(L14<4172.98,0,MIN(L14*0.3,L14-4172.98)))-M14 -> 541.196 | P14: 46935 | Q14: DIMEX | R14: 803.54 | S14: HECTOR
A15: 24172054 | B15: 46266 | C15: 0.70646991 | E15: 5216531740815 | H15: 23926510993 | K15: NUEVO MAYOR | L15: =8881.32+879 -> 9760.32 | M15: 879 | N15: =L15*0.3 -> 2928.096 | O15: =(IF(L15<4172.98,0,MIN(L15*0.3,L15-4172.98)))-M15 -> 2049.096 | S15: MARISOL
A16: 24172624 | B16: 46266 | C16: 0.72210648 | E16: 5218128785655 | H16: 43856563408 | K16: NUEVO MAYOR | L16: 21040.93 | M16: 1639.52 | N16: =L16*0.3 -> 6312.279 | O16: =(IF(L16<4172.98,0,MIN(L16*0.3,L16-4172.98)))-M16 -> 4672.759 | P16: 46935 | Q16: FIMUBAC | R16: 692.75 | S16: KARINA
A17: 24172910 | B17: 46266 | C17: 0.73425926 | E17: 5214131415809 | G17: BEMS660208MGTRNL08 | K17: NUEVO MAYOR | L17: 10636.54 | N17: =L17*0.3 -> 3190.962 | O17: =(IF(L17<4172.98,0,MIN(L17*0.3,L17-4172.98)))-M17 -> 3190.962 | S17: DANIELLY
A18: 24174022 | B18: 46266 | C18: 0.75701389 | E18: 5215649941915 | G18: CABC711002HYNSCR01 | K18: COMPRA MENOR | L18: 4998.54 | M18: 511.34 | N18: =L18*0.3 -> 1499.562 | O18: =(IF(L18<4172.98,0,MIN(L18*0.3,L18-4172.98)))-M18 -> 314.22 | P18: 45383 | Q18: DIMEX | R18: 511.34 | S18: HANIA
A19: 24174378 | B19: 46266 | C19: 0.75961806 | D19: DE JESUS VILLANUEVA DOROTEO | E19: 5217411381143 | G19: JEVD430909HGRSLR09 | K19: COMPRA MAYOR | L19: 13159.31 | M19: 2851.99 | N19: =L19*0.3 -> 3947.793 | O19: =(IF(L19<4172.98,0,MIN(L19*0.3,L19-4172.98)))-M19 -> 1095.803 | P19: 45717 | Q19: EXITUS | R19: 2851.99 | S19: ANA
A20: 24174234 | B20: 46266 | C20: 0.76256944 | E20: 5219992506888 | H20: 84846306854 | K20: NUEVO MAYOR | L20: 50623 | N20: =L20*0.3 -> 15186.9 | O20: =(IF(L20<4172.98,0,MIN(L20*0.3,L20-4172.98)))-M20 -> 15186.9 | S20: ITZELH
A21: 24175106 | B21: 46266 | C21: 0.77946759 | E21: 5215530653088 | G21: RURA810909HDFZZN06 | K21: NUEVO MAYOR | L21: 7073.35 | N21: =L21*0.3 -> 2122.005 | O21: =(IF(L21<4172.98,0,MIN(L21*0.3,L21-4172.98)))-M21 -> 2122.005 | S21: FERNANDA
A22: 24175518 | B22: 46266 | C22: 0.79244213 | E22: 5212298581278 | G22: MIVA550510HMCLLN06 | H22: 1735569640 | K22: NUEVO MAYOR | L22: 23364.8 | N22: =L22*0.3 -> 7009.44 | O22: =(IF(L22<4172.98,0,MIN(L22*0.3,L22-4172.98)))-M22 -> 7009.44 | S22: IRASEMA
A23: 24176370 | B23: 46266 | C23: 0.81753472 | E23: 5215537061044 | H23: 19745825505 | K23: NUEVO MAYOR | L23: =7041.51+879 -> 7920.51 | M23: 879 | N23: =L23*0.3 -> 2376.153 | O23: =(IF(L23<4172.98,0,MIN(L23*0.3,L23-4172.98)))-M23 -> 1497.153 | S23: GLORIA
A24: 24176428 | B24: 46266 | C24: 0.82177083 | E24: 5213310204743 | G24: Gohl641002hdfnrs03 | K24: NUEVO MAYOR | L24: 50522.01 | N24: =L24*0.3 -> 15156.603 | O24: =(IF(L24<4172.98,0,MIN(L24*0.3,L24-4172.98)))-M24 -> 15156.603 | S24: MIRIAM
A25: 24176270 | B25: 46266 | C25: 0.82173611 | E25: 5218116555750 | H25: 43796319044 | K25: RESTRINGIDA | L25: 7920.581 | M25: 2081.72 | N25: =L25*0.3 -> 2376.1743 | O25: =(IF(L25<4172.98,0,MIN(L25*0.3,L25-4172.98)))-M25 -> 294.4543 | P25: 46023 | Q25: FISOFO | R25: 2081.72 | S25: DANIELLY
A26: 24177220 | B26: 46266 | C26: 0.85467593 | E26: 5218186835859 | H26: 32917428396 | K26: NUEVO MAYOR | L26: =41204.62-31622.15 -> 9582.47 | N26: =L26*0.3 -> 2874.741 | O26: =(IF(L26<4172.98,0,MIN(L26*0.3,L26-4172.98)))-M26 -> 2874.741 | S26: PAOLA
A27: 24179252 | B27: 46266 | C27: 0.92521991 | E27: 5218714710529 | G27: PuRJ601015HCLNSS07 | K27: RESTRINGIDA | L27: 6460.14 | M27: 786.39 | N27: =L27*0.3 -> 1938.042 | O27: =(IF(L27<4172.98,0,MIN(L27*0.3,L27-4172.98)))-M27 -> 1151.652 | P27: 45809 | Q27: CONSUBANCO | R27: 786.39 | S27: DANIELLY
A28: 24186106 | B28: 46267 | C28: 0.27892361 | E28: 5218711564700 | H28: 33856507042 | K28: NUEVO MAYOR | L28: =8881.32+879 -> 9760.32 | M28: 879 | N28: =L28*0.3 -> 2928.096 | O28: =(IF(L28<4172.98,0,MIN(L28*0.3,L28-4172.98)))-M28 -> 2049.096 | S28: EDNA
A29: 24186924 | B29: 46267 | C29: 0.30706019 | E29: 5212291029648 | H29: 65796045709 | K29: COMPRA MENOR | L29: 28001.73 | M29: 8397.98 | N29: =L29*0.3 -> 8400.519 | O29: =(IF(L29<4172.98,0,MIN(L29*0.3,L29-4172.98)))-M29 -> 2.539 | P29: 46143 | Q29: BANCREA | R29: 360 | S29: HECTOR
A30: 24179126 | B30: 46267 | C30: 0.46449074 | E30: 6561859034 | G30: heaj640614hchrrs02 | H30: 33836434127 | K30: COMPRA MAYOR | L30: 9081.52 | M30: 2518.28 | N30: =L30*0.3 -> 2724.456 | O30: =(IF(L30<4172.98,0,MIN(L30*0.3,L30-4172.98)))-M30 -> 206.176 | P30: 46235 | Q30: INBURSA | R30: 2518.28 | S30: FERNANDA
A31: 24194642 | B31: 46267 | C31: 0.4771412 | E31: 5219911001910 | G31: PECE621027HYNCHR06 | K31: NUEVO MAYOR | L31: 7116.73 | N31: =L31*0.3 -> 2135.019 | O31: =(IF(L31<4172.98,0,MIN(L31*0.3,L31-4172.98)))-M31 -> 2135.019 | S31: PAOLA
A32: 24195644 | B32: 46267 | C32: 0.50653935 | E32: 5216441391798 | G32: LECE620510HSRLLD02 | K32: COMPRA MAYOR | L32: 7116.73 | M32: 1887 | N32: =L32*0.3 -> 2135.019 | O32: =(IF(L32<4172.98,0,MIN(L32*0.3,L32-4172.98)))-M32 -> 248.019 | P32: 45931 | Q32: MULTIVA | R32: 1887 | S32: FERNANDA
A33: 24199408 | B33: 46267 | C33: 0.60513889 | E33: 5218125802778 | H33: 43796074813 | K33: COMPRA MENOR | L33: 6269.7 | M33: 1813.01 | N33: =L33*0.3 -> 1880.91 | O33: =(IF(L33<4172.98,0,MIN(L33*0.3,L33-4172.98)))-M33 -> 67.9 | P33: 45748 | Q33: DIMEX | R33: 355.85 | S33: HANIA
A34: 24199760 | B34: 46267 | C34: 0.62016204 | E34: 5215543747951 | G34: RURR630829MDFZSS09 | K34: NUEVO MAYOR | L34: 9612.19 | N34: =L34*0.3 -> 2883.657 | O34: =(IF(L34<4172.98,0,MIN(L34*0.3,L34-4172.98)))-M34 -> 2883.657 | S34: KARINA
A35: 24199870 | B35: 46267 | C35: 0.62028935 | E35: 5215562169296 | G35: SOBR570919HMCTNG04 | K35: RESTRINGIDA | L35: 10247.51 | M35: 2964 | N35: =L35*0.3 -> 3074.253 | O35: =(IF(L35<4172.98,0,MIN(L35*0.3,L35-4172.98)))-M35 -> 110.253 | P35: 46204 | Q35: CONSUBANCO | R35: 2232.8 | S35: DANIELLY
A36: 24200274 | B36: 46267 | C36: 0.63262731 | E36: 5212221150207 | H36: 62806241899 | K36: RESTRINGIDA | L36: 7116.73 | M36: 516.92 | N36: =L36*0.3 -> 2135.019 | O36: =(IF(L36<4172.98,0,MIN(L36*0.3,L36-4172.98)))-M36 -> 1618.099 | P36: 45748 | Q36: CONSUBANCO | R36: 516.92 | S36: DANIELLY
A37: 24200472 | B37: 46267 | C37: 0.63975694 | E37: 5218136084482 | G37: VIFA640701HTSLLR03 | K37: NUEVO MAYOR | L37: 10636.54 | N37: =L37*0.3 -> 3190.962 | O37: =(IF(L37<4172.98,0,MIN(L37*0.3,L37-4172.98)))-M37 -> 3190.962 | S37: IRASEMA
A38: 24200638 | B38: 46267 | C38: 0.64934028 | D38: GUILLERMO TALAVERA SILVA | E38: 5212711269633 | G38: TASM590502HVZLLL08 | H38: 67775921397 | K38: NUEVO MENOR | L38: 4813.69 | N38: =L38*0.3 -> 1444.107 | O38: =(IF(L38<4172.98,0,MIN(L38*0.3,L38-4172.98)))-M38 -> 640.71 | S38: HECTOR
A39: 24201574 | B39: 46267 | C39: 0.67907407 | E39: 5215561277808 | H39: 3992630961-6 | K39: NUEVO MAYOR | L39: =42546.16-31909.62 -> 10636.54 | N39: =L39*0.3 -> 3190.962 | O39: =(IF(L39<4172.98,0,MIN(L39*0.3,L39-4172.98)))-M39 -> 3190.962 | S39: ITZELH
A40: 24201552 | B40: 46267 | C40: 0.67946759 | E40: 5217228677012 | G40: FALR490113HDFRNF09 | K40: COMPRA MAYOR | L40: 13266.31 | M40: 3461.12 | N40: =L40*0.3 -> 3979.893 | O40: =(IF(L40<4172.98,0,MIN(L40*0.3,L40-4172.98)))-M40 -> 518.773 | P40: 46054 | Q40: PROFUTURO | R40: 2353.61 | S40: CAROLINA
...

Sheet Hoja6
A1: Fecha asignacion | B1: 46294
A3: Recuento de ESTATUS | B3: ESTATUS
A4: Asignado | B4: COMPRA MAYOR | C4: NUEVO MAYOR | D4: NUEVO MENOR | E4: RESTRINGIDA | F4: Total general
A5: IRASEMA | D5: 2 | F5: 2
A6: ITZEL CARRANZA | B6: 1 | C6: 1 | F6: 2
A7: MAYTE | C7: 1 | F7: 1
A8: BEATRIZ | D8: 4 | F8: 4
A9: GUADALUPE | E9: 1 | F9: 1
A10: LUZ | C10: 2 | F10: 2
A11: JAEL | C11: 1 | F11: 1
A12: Total general | B12: 1 | C12: 5 | D12: 6 | E12: 1 | F12: 13

Sheet ASIGNACIONES
A1: LEAD | B1: TELEFONO | C1: ESTATUS | D1: INFORMEDEPAGO | E1: DESCUENTOS | F1: $0.30 | G1: CAPACIDAD | H1: VENCIMIENTO | I1: FINANCIERA | J1: Monto compra | K1: Asignado | L1: Fecha asignacion
A2: 23726144 | B2: 5219541548449 | C2: NUEVO MENOR | D2: 15280.15 | E2: 4046.08 | F2: =D2*0.3 -> 4584.045 | G2: =(IF(D2<4172.98,0,MIN(D2*0.3,D2-4172.98)))-E2 -> 537.965 | K2: HECTOR | L2: 46253
A3: 23756661 | B3: 5214776735685 | C3: NUEVO MAYOR | D3: 9290.75 | F3: =D3*0.3 -> 2787.225 | G3: =(IF(D3<4172.98,0,MIN(D3*0.3,D3-4172.98)))-E3 -> 2787.225 | K3: MELANIE | L3: 46253
A4: 23706370 | B4: 6444470845 | C4: NUEVO MAYOR | D4: 9760.32 | F4: =D4*0.3 -> 2928.096 | G4: =(IF(D4<4172.98,0,MIN(D4*0.3,D4-4172.98)))-E4 -> 2928.096 | K4: ITZEL CARRANZA | L4: 46253
A5: 23761287 | B5: 8124440400 | C5: COMPRA MAYOR | D5: 8592.73 | E5: 2385.73 | F5: =D5*0.3 -> 2577.819 | G5: =(IF(D5<4172.98,0,MIN(D5*0.3,D5-4172.98)))-E5 -> 192.089 | H5: 46235 | K5: MELANIE | L5: 46253
A6: 23762769 | B6: 5212221625726 | C6: NUEVO MAYOR | D6: 21036.47 | E6: 1533.09 | F6: =D6*0.3 -> 6310.941 | G6: =(IF(D6<4172.98,0,MIN(D6*0.3,D6-4172.98)))-E6 -> 4777.851 | H6: 46447 | K6: ANA | L6: 46253
A7: 23742131 | B7: 5216145090575 | C7: NUEVO MAYOR | D7: =88669.49-80969.29 -> 7700.2 | F7: =D7*0.3 -> 2310.06 | G7: =(IF(D7<4172.98,0,MIN(D7*0.3,D7-4172.98)))-E7 -> 2310.06 | K7: PAOLA | L7: 46253
A8: 23757641 | B8: 5212225682011 | C8: NUEVO MAYOR | D8: 9760.32 | F8: =D8*0.3 -> 2928.096 | G8: =(IF(D8<4172.98,0,MIN(D8*0.3,D8-4172.98)))-E8 -> 2928.096 | K8: ITZEL CARRANZA | L8: 46253
A9: 23766780 | B9: 2721532069 | C9: NUEVO MENOR | D9: 5617.63 | E9: 1000 | F9: =D9*0.3 -> 1685.289 | G9: =(IF(D9<4172.98,0,MIN(D9*0.3,D9-4172.98)))-E9 -> 444.65 | H9: 46722 | K9: HECTOR | L9: 46253
A10: 23763509 | B10: 5213312837635 | C10: RESTRINGIDA | D10: 4172.53 | E10: 375 | F10: =D10*0.3 -> 1251.759 | G10: =(IF(D10<4172.98,0,MIN(D10*0.3,D10-4172.98)))-E10 -> -375 | H10: 46204 | I10: CONSUBANCO | K10: DANIELLY | L10: 46253
A11: 23770102 | B11: 5213320114300 | C11: NUEVO MAYOR | D11: 13720.49 | F11: =D11*0.3 -> 4116.147 | G11: =(IF(D11<4172.98,0,MIN(D11*0.3,D11-4172.98)))-E11 -> 4116.147 | K11: DANIELLY | L11: 46253
A12: 23769606 | B12: 3122727690 | C12: COMPRA MENOR | D12: 4813.69 | E12: 592.94 | F12: =D12*0.3 -> 1444.107 | G12: =(IF(D12<4172.98,0,MIN(D12*0.3,D12-4172.98)))-E12 -> 47.77 | H12: 46174 | K12: HECTOR | L12: 46253
A13: 23772894 | B13: 5217441786998 | C13: RESTRINGIDA | D13: 10266.12 | E13: 2516.68 | F13: =D13*0.3 -> 3079.836 | G13: =(IF(D13<4172.98,0,MIN(D13*0.3,D13-4172.98)))-E13 -> 563.156 | H13: 45505 | I13: FISOFO | J13: 2516.68 | K13: DANIELLY | L13: 46253
A14: 23760627 | B14: 3312602707 | C14: NUEVO MENOR | D14: 4938.19 | F14: =D14*0.3 -> 1481.457 | G14: =(IF(D14<4172.98,0,MIN(D14*0.3,D14-4172.98)))-E14 -> 765.21 | K14: HANIA | L14: 46253
A15: 23737786 | C15: NUEVO MENOR | D15: =5460.44+818.69 -> 6279.13 | E15: 818.69 | F15: =D15*0.3 -> 1883.739 | G15: =(IF(D15<4172.98,0,MIN(D15*0.3,D15-4172.98)))-E15 -> 1065.049 | H15: 46692 | I15: INBURSA | J15: 818.69 | K15: HANIA | L15: 46253
A16: 23737964 | C16: NUEVO MAYOR | D16: 10636.54 | F16: =D16*0.3 -> 3190.962 | G16: =(IF(D16<4172.98,0,MIN(D16*0.3,D16-4172.98)))-E16 -> 3190.962 | K16: MAGALI | L16: 46253
A17: 23738744 | C17: NUEVO MAYOR | D17: 8179.32 | F17: =D17*0.3 -> 2453.796 | G17: =(IF(D17<4172.98,0,MIN(D17*0.3,D17-4172.98)))-E17 -> 2453.796 | K17: MELANIE | L17: 46253
A18: 23739672 | C18: NUEVO MAYOR | D18: 16623.22 | F18: =D18*0.3 -> 4986.966 | G18: =(IF(D18<4172.98,0,MIN(D18*0.3,D18-4172.98)))-E18 -> 4986.966 | K18: MIRIAM | L18: 46253
A19: 23740390 | C19: NUEVO MAYOR | D19: 9760.32 | F19: =D19*0.3 -> 2928.096 | G19: =(IF(D19<4172.98,0,MIN(D19*0.3,D19-4172.98)))-E19 -> 2928.096 | K19: ANA | L19: 46253
A20: 23740420 | C20: NUEVO MAYOR | D20: 7920.51 | F20: =D20*0.3 -> 2376.153 | G20: =(IF(D20<4172.98,0,MIN(D20*0.3,D20-4172.98)))-E20 -> 2376.153 | K20: ITZEL CARRANZA | L20: 46253
A21: 23741302 | C21: NUEVO MAYOR | D21: 5869.14 | F21: =D21*0.3 -> 1760.742 | G21: =(IF(D21<4172.98,0,MIN(D21*0.3,D21-4172.98)))-E21 -> 1696.16 | K21: GLORIA | L21: 46253
A22: 23744477 | C22: NUEVO MAYOR | D22: 5427.74 | F22: =D22*0.3 -> 1628.322 | G22: =(IF(D22<4172.98,0,MIN(D22*0.3,D22-4172.98)))-E22 -> 1254.76 | K22: GLORIA | L22: 46253
A23: 23750439 | C23: NUEVO MENOR | D23: 4990.99 | F23: =D23*0.3 -> 1497.297 | G23: =(IF(D23<4172.98,0,MIN(D23*0.3,D23-4172.98)))-E23 -> 818.01 | K23: HECTOR | L23: 46253
A24: 23758273 | C24: COMPRA MAYOR | D24: =5764.33+1876.19 -> 7640.52 | E24: 1876.19 | F24: =D24*0.3 -> 2292.156 | G24: =(IF(D24<4172.98,0,MIN(D24*0.3,D24-4172.98)))-E24 -> 415.966 | H24: 45597 | I24: BANCREA | J24: 1876.19 | K24: PAOLA | L24: 46253
A25: 23759367 | C25: NUEVO MAYOR | D25: 11029.03 | F25: =D25*0.3 -> 3308.709 | G25: =(IF(D25<4172.98,0,MIN(D25*0.3,D25-4172.98)))-E25 -> 3308.709 | K25: MAGALI | L25: 46253
A26: 23759203 | C26: NUEVO MAYOR | D26: 9760.32 | F26: =D26*0.3 -> 2928.096 | G26: =(IF(D26<4172.98,0,MIN(D26*0.3,D26-4172.98)))-E26 -> 2928.096 | K26: ANA | L26: 46253
A27: 23762117 | C27: NUEVO MAYOR | D27: 10636.54 | F27: =D27*0.3 -> 3190.962 | G27: =(IF(D27<4172.98,0,MIN(D27*0.3,D27-4172.98)))-E27 -> 3190.962 | K27: MIRIAM | L27: 46253
A28: 23762755 | C28: COMPRA MAYOR | D28: =5230.75+1885.98 -> 7116.73 | E28: 1885.98 | F28: =D28*0.3 -> 2135.019 | G28: =(IF(D28<4172.98,0,MIN(D28*0.3,D28-4172.98)))-E28 -> 249.039 | H28: 45689 | I28: DIMEX | J28: 1885.98 | K28: CAROLINA | L28: 46253
A29: 23763013 | C29: NUEVO MENOR | D29: 5264.19 | F29: =D29*0.3 -> 1579.257 | G29: =(IF(D29<4172.98,0,MIN(D29*0.3,D29-4172.98)))-E29 -> 1091.21 | K29: HANIA | L29: 46253
A30: 23763727 | C30: COMPRA MAYOR | D30: 32694.08 | E30: 8776.16 | F30: =D30*0.3 -> 9808.224 | G30: =(IF(D30<4172.98,0,MIN(D30*0.3,D30-4172.98)))-E30 -> 1032.064 | H30: 46204 | I30: MULTIVA | J30: 8776.16 | K30: MIRIAM | L30: 46253
A31: 23763821 | C31: NUEVO MAYOR | D31: 7920.51 | F31: =D31*0.3 -> 2376.153 | G31: =(IF(D31<4172.98,0,MIN(D31*0.3,D31-4172.98)))-E31 -> 2376.153 | K31: PAOLA | L31: 46253
A32: 23764709 | C32: NUEVO MAYOR | D32: 34782.28 | F32: =D32*0.3 -> 10434.684 | G32: =(IF(D32<4172.98,0,MIN(D32*0.3,D32-4172.98)))-E32 -> 10434.684 | K32: GABRIELA | L32: 46253
A33: 23766332 | C33: NUEVO MAYOR | D33: 21696.27 | F33: =D33*0.3 -> 6508.881 | G33: =(IF(D33<4172.98,0,MIN(D33*0.3,D33-4172.98)))-E33 -> 6508.881 | K33: IRASEMA | L33: 46253
A34: 23766172 | C34: NUEVO MAYOR | D34: 9081.52 | E34: 848 | F34: =D34*0.3 -> 2724.456 | G34: =(IF(D34<4172.98,0,MIN(D34*0.3,D34-4172.98)))-E34 -> 1876.456 | K34: CAROLINA | L34: 46253
A35: 23767716 | C35: NUEVO MAYOR | D35: 15829.2 | F35: =D35*0.3 -> 4748.76 | G35: =(IF(D35<4172.98,0,MIN(D35*0.3,D35-4172.98)))-E35 -> 4748.76 | K35: IRASEMA | L35: 46253
A36: 23770750 | C36: NUEVO MENOR | D36: 9760.32 | E36: 2291.11 | F36: =D36*0.3 -> 2928.096 | G36: =(IF(D36<4172.98,0,MIN(D36*0.3,D36-4172.98)))-E36 -> 636.986 | H36: 46539 | I36: PROFUTURO | J36: 2291.11 | K36: HANIA | L36: 46253
A37: 23772642 | C37: NUEVO MAYOR | D37: 11344.78 | F37: =D37*0.3 -> 3403.434 | G37: =(IF(D37<4172.98,0,MIN(D37*0.3,D37-4172.98)))-E37 -> 3403.434 | K37: IRASEMA | L37: 46253
A38: 23772650 | C38: NUEVO MAYOR | D38: 23704.43 | F38: =D38*0.3 -> 7111.329 | G38: =(IF(D38<4172.98,0,MIN(D38*0.3,D38-4172.98)))-E38 -> 7111.329 | K38: DANIELLY | L38: 46253
A39: 23772790 | C39: NUEVO MAYOR | D39: 10636.54 | F39: =D39*0.3 -> 3190.962 | G39: =(IF(D39<4172.98,0,MIN(D39*0.3,D39-4172.98)))-E39 -> 3190.962 | K39: MAGALI | L39: 46253
A40: 23774854 | C40: NUEVO MAYOR | D40: 6262.86 | F40: =D40*0.3 -> 1878.858 | G40: =(IF(D40<4172.98,0,MIN(D40*0.3,D40-4172.98)))-E40 -> 1878.858 | K40: CAROLINA | L40: 46253
...

Sheet LISTA
A1: NUEVO MAYOR
A2: NO DATO
A3: COMPRA BIMESTRES
A4: COMPRA MAYOR
A5: NUEVO MENOR
A6: SIN CAPACIDAD
A7: RESTRINGIDA
A8: COMPRA MENOR
A9: LEY 97
A10: SIN NOMINA
A11: NEGOCIO DUPLICADO
A12: P.V.
A13: JUBILADO N.M.

Sheet Informes
A1: HORARIOS | C1: 46237 | G1: HORARIOS | I1: 46238 | M1: HORARIOS | O1: 46239 | S1: HORARIOS | U1: 46240 | Y1: HORARIOS | AA1: 46241 | AE1: HORARIOS | AG1: 46242 | AK1: HORARIOS | AM1: 46244 | AQ1: HORARIOS | AS1: 46245 | AW1: HORARIOS | AY1: 46246 | BC1: HORARIOS | BE1: 46247 | BI1: HORARIOS | BK1: 46248 | BO1: HORARIOS | BQ1: 46249 | BU1: HORARIOS | BW1: 46250 | CA1: HORARIOS | CC1: 46251 | CG1: HORARIOS | CI1: 46252 | CM1: HORARIOS | CO1: 46253 | CS1: HORARIOS | CU1: 46254 | CY1: HORARIOS | DA1: 46255 | DE1: HORARIOS | DG1: 46256 | DK1: HORARIOS | DM1: 46258 | DQ1: HORARIOS | DT1: 46265 | DX1: HORARIOS | EA1: 46266 | EE1: HORARIOS | EH1: 46267 | EL1: HORARIOS | EO1: 46268 | ES1: HORARIOS | EV1: 46269 | EZ1: HORARIOS | FC1: 46270 | FG1: HORARIOS | FJ1: 46272 | FN1: HORARIOS | FQ1: 46273 | FU1: HORARIOS | FX1: 46274 | GB1: HORARIOS | GE1: 46275 | GI1: HORARIOS | GL1: 46276 | GP1: HORARIOS | GS1: 46277 | GW1: HORARIOS | GZ1: 46279 | HD1: HORARIOS | HG1: 46280 | HK1: HORARIOS | HN1: 46282 | HR1: HORARIOS | HU1: 46283 | HY1: HORARIOS | IB1: 46286 | IF1: HORARIOS | II1: 46287 | IM1: HORARIOS | IP1: 46288 | IT1: HORARIOS | IW1: 46289 | JA1: HORARIOS | JD1: 46290 | JH1: HORARIOS | JK1: 46292 | JO1: HORARIOS | JR1: 46293 | JV1: HORARIOS | JY1: 46294
A2: ASESOR | B2: LEAD | C2: ASIGNACION | D2: ATENCION | G2: ASESOR | H2: LEAD | I2: ASIGNACION | J2: ATENCION | M2: ASESOR | N2: LEAD | O2: ASIGNACION | P2: ATENCION | S2: ASESOR | T2: LEAD | U2: ASIGNACION | V2: ATENCION | Y2: ASESOR | Z2: LEAD | AA2: ASIGNACION | AB2: ATENCION | AE2: ASESOR | AF2: LEAD | AG2: ASIGNACION | AH2: ATENCION | AK2: ASESOR | AL2: LEAD | AM2: ASIGNACION | AN2: ATENCION | AQ2: ASESOR | AR2: LEAD | AS2: ASIGNACION | AT2: ATENCION | AW2: ASESOR | AX2: LEAD | AY2: ASIGNACION | AZ2: ATENCION | BC2: ASESOR | BD2: LEAD | BE2: ASIGNACION | BF2: ATENCION | BI2: ASESOR | BJ2: LEAD | BK2: ASIGNACION | BL2: ATENCION | BO2: ASESOR | BP2: LEAD | BQ2: ASIGNACION | BR2: ATENCION | BU2: ASESOR | BV2: LEAD | BW2: ASIGNACION | BX2: ATENCION | CA2: ASESOR | CB2: LEAD | CC2: ASIGNACION | CD2: ATENCION | CG2: ASESOR | CH2: LEAD | CI2: ASIGNACION | CJ2: ATENCION | CM2: ASESOR | CN2: LEAD | CO2: ASIGNACION | CP2: ATENCION | CS2: ASESOR | CT2: LEAD | CU2: ASIGNACION | CV2: ATENCION | CY2: ASESOR | CZ2: LEAD | DA2: ASIGNACION | DB2: ATENCION | DE2: ASESOR | DF2: LEAD | DG2: ASIGNACION | DH2: ATENCION | DK2: ASESOR | DL2: LEAD | DM2: ASIGNACION | DN2: ATENCION | DQ2: ASESOR | DR2: LEAD | DS2: PANTALLA | DT2: ASIGNACION | DU2: ATENCION | DX2: ASESOR | DY2: LEAD | DZ2: PANTALLA | EA2: ASIGNACION | EB2: ATENCION | EE2: ASESOR | EF2: LEAD | EG2: PANTALLA | EH2: ASIGNACION | EI2: ATENCION | EL2: ASESOR | EM2: LEAD | EN2: PANTALLAS | EO2: ASIGNACION | EP2: ATENCION | ES2: ASESOR | ET2: LEAD | EU2: PANTALLAS | EV2: ASIGNACION | EW2: ATENCION | EZ2: ASESOR | FA2: LEAD | FB2: PANTALLAS | FC2: ASIGNACION | FD2: ATENCION | FG2: ASESOR | FH2: LEAD | FI2: PANTALLAS | FJ2: ASIGNACION | FK2: ATENCION | FN2: ASESOR | FO2: LEAD | FP2: PANTALLAS | FQ2: ASIGNACION | FR2: ATENCION | FU2: ASESOR | FV2: LEAD | FW2: PANTALLAS | FX2: ASIGNACION | FY2: ATENCION | GB2: ASESOR | GC2: LEAD | GD2: PANTALLAS | GE2: ASIGNACION | GF2: ATENCION | GI2: ASESOR | GJ2: LEAD | GK2: PANTALLAS | GL2: ASIGNACION | GM2: ATENCION | GP2: ASESOR | GQ2: LEAD | GR2: PANTALLAS | GS2: ASIGNACION | GT2: ATENCION | GW2: ASESOR | GX2: LEAD | GY2: PANTALLAS | GZ2: ASIGNACION | HA2: ATENCION | HD2: ASESOR | HE2: LEAD | HF2: PANTALLAS | HG2: ASIGNACION | HH2: ATENCION | HK2: ASESOR | HL2: LEAD | HM2: PANTALLAS | HN2: ASIGNACION | HO2: ATENCION | HR2: ASESOR | HS2: LEAD | HT2: PANTALLAS | HU2: ASIGNACION | HV2: ATENCION | HY2: ASESOR | HZ2: LEAD | IA2: PANTALLAS | IB2: ASIGNACION | IC2: ATENCION | IF2: ASESOR | IG2: LEAD | IH2: PANTALLAS | II2: ASIGNACION | IJ2: ATENCION | IM2: ASESOR | IN2: LEAD | IO2: PANTALLAS | IP2: ASIGNACION | IQ2: ATENCION | IT2: ASESOR | IU2: LEAD | IV2: PANTALLAS | IW2: ASIGNACION | IX2: ATENCION | JA2: ASESOR | JB2: LEAD | JC2: PANTALLAS | JD2: ASIGNACION | JE2: ATENCION | JH2: ASESOR | JI2: LEAD | JJ2: PANTALLAS | JK2: ASIGNACION | JL2: ATENCION | JO2: ASESOR | JP2: LEAD | JQ2: PANTALLAS | JR2: ASIGNACION | JS2: ATENCION | JV2: ASESOR | JW2: LEAD | JX2: PANTALLAS | JY2: ASIGNACION | JZ2: ATENCION
A3: Irasema | B3: 23298744 | C3: 0.54444444 | D3: 0.54652778 | G3: Irasema | H3: 23352780 | I3: 0.45 | J3: 0.45069444 | M3: Irasema | N3: 23376448 | O3: 0.40208333 | P3: 0.40416667 | S3: Irasema | T3: 23408734 | U3: 0.39236111 | V3: 0.39444444 | Y3: Miriam | Z3: 23435326 | AA3: 0.39652778 | AB3: 0.39722222 | AE3: Miriam | AF3: 23461252 | AG3: 0.39791667 | AH3: 0.39930556 | AK3: Miriam | AL3: 23490340 | AM3: 0.41180556 | AN3: 0.41319444 | AQ3: Dulce | AR3: 23525578 | AS3: 0.43055556 | AT3: 0.43958333 | AW3: Fernanda | AX3: 23552710 | AY3: 0.40347222 | AZ3: 0.40972222 | BC3: Itzelh | BD3: 23581752 | BE3: 0.40069444 | BF3: 0.40555556 | BI3: Fernanda | BJ3: 23615044 | BK3: 0.40138889 | BL3: 0.40555556 | BO3: Adela | BP3: 23648218 | BQ3: 0.38888889 | BR3: 0.39652778 | BU3: Gabriela | BV3: 23657810 | BW3: 0.59236111 | BX3: 0.62083333 | CA3: Miriam | CB3: 23677584 | CC3: 0.42083333 | CD3: 0.42152778 | CG3: Itzelh | CH3: 23708962 | CI3: 0.40069444 | CJ3: 0.40277778 | CL3: * | CM3: Melanie | CN3: 23756661 | CO3: 0.47083333 | CP3: 0.47916667 | CR3: * | CS3: Melanie | CT3: 23766352 | CU3: 0.38888889 | CV3: 0.40069444 | CX3: * | CY3: Itzel Carranza | CZ3: 23737228 | DA3: 0.44513889 | DB3: 0.44652778 | DD3: * | DE3: Hector | DF3: 23673046 | DG3: 0.56388889 | DH3: 0.56666667 | DJ3: * | DK3: Miriam | DL3: 23812196 | DM3: 0.40833333 | DN3: 0.40972222 | DP3: * | DQ3: Miriam | DR3: 24117438 | DS3: 0.40625 | DT3: 0.41736111 | DU3: 0.41805556 | DW3: * | DX3: Itzelh | DY3: 24153432 | DZ3: 0.4375 | EA3: 0.44097222 | EB3: 0.44305556 | ED3: * | EE3: Ana | EF3: 24151366 | EG3: 0.43958333 | EH3: 0.44305556 | EI3: 0.45 | EK3: * | EL3: Edna | EM3: 24209764 | EN3: 0.45 | EO3: 0.45347222 | EP3: 0.46041667 | ES3: HECTOR | ET3: 24223350 | EU3: 0.39861111 | EV3: 0.40833333 | EW3: 0.41041667 | EZ3: PAOLA | FA3: 24254260 | FB3: 0.78819444 | FC3: 0.4375 | FD3: 0.43888889 | FG3: DANIELLY | FH3: 24257186 | FI3: 0.38819444 | FJ3: 0.41736111 | FK3: 0.41805556 | FN3: HECTOR | FO3: 24314542 | FP3: 0.40069444 | FQ3: 0.40347222 | FR3: 0.40486111 | FU3: ITZEL CARRANZA | FV3: 24328262 | FW3: 0.35833333 | FX3: 0.40486111 | FY3: 0.41180556 | GB3: MAGALI | GC3: 24372336 | GD3: 0.49513889 | GE3: 0.50625 | GF3: 0.50694444 | GI3: HANIA | GJ3: 24383414 | GK3: 0.41805556 | GL3: 0.42708333 | GM3: 0.42847222 | GP3: EDNA | GQ3: 24393582 | GR3: 0.35902778 | GS3: 0.36319444 | GT3: 0.36388889 | GW3: ANDRE | GX3: 24424018 | GY3: 0.37777778 | GZ3: 0.39166667 | HA3: 0.39305556 | HD3: YESSENIA | HE3: 24433794 | HF3: 0.40208333 | HG3: 0.41597222 | HH3: 0.44375 | HK3: PAOLA | HL3: 24490714 | HM3: 0.33888889 | HN3: 0.34305556 | HO3: 0.34375 | HR3: LIDIA | HS3: 24283370 | HT3: 0.39513889 | HU3: 0.40347222 | HV3: 0.41597222 | HY3: IRASEMA | HZ3: 24150820 | IA3: 0.44444444 | IB3: 0.45555556 | IC3: 0.45763889 | IF3: CAROLINA | IG3: 24680220 | IH3: 0.36180556 | II3: 0.36319444 | IJ3: 0.36458333 | IM3: HECTOR | IN3: 24749710 | IO3: 0.39513889 | IP3: 0.39791667 | IQ3: 0.41388889 | IT3: PAOLA | IU3: 24800070 | IV3: 0.60555556 | IW3: 0.61388889 | IX3: 0.61527778 | JA3: GUADALUPE | JB3: 24832784 | JC3: 0.44097222 | JD3: 0.44305556 | JE3: 0.45 | JH3: KATE | JI3: 24747080 | JJ3: 0.63402778 | JK3: 0.63680556 | JL3: X | JO3: GUADALUPE | JP3: 24855346 | JQ3: 0.43125 | JR3: 0.44236111 | JS3: 0.47152778 | JV3: BEATRIZ | JW3: 24901938 | JX3: 0.35972222 | JY3: 0.36041667 | JZ3: 0.36180556
A4: Irasema | B4: 23300706 | C4: 0.54791667 | D4: 0.54861111 | G4: Hector | H4: 23353384 | I4: 0.45486111 | J4: 0.45833333 | M4: Hector | N4: 23377394 | O4: 0.40555556 | P4: 0.41111111 | S4: Itzelh | T4: 23409174 | U4: 0.39375 | V4: 0.39861111 | Y4: Carolina | Z4: 23436306 | AA4: 0.40486111 | AB4: 0.40694444 | AE4: Carolina | AF4: 23461636 | AG4: 0.40277778 | AH4: 0.40555556 | AK4: Itzelh | AL4: 23494530 | AM4: 0.41458333 | AN4: 0.41597222 | AQ4: Miriam | AR4: 23527758 | AS4: 0.43333333 | AT4: 0.43472222 | AW4: Dulce | AX4: 23567382 | AY4: 0.40694444 | AZ4: 0.41319444 | BC4: Marisol | BD4: 23581914 | BE4: 0.40277778 | BF4: 0.40416667 | BI4: Marisol | BJ4: 23615376 | BK4: 0.40625 | BL4: 0.40763889 | BO4: Adela | BP4: 23652612 | BQ4: 0.4 | BR4: 0.40972222 | BU4: Dulce | BV4: 23613822 | BW4: 0.67291667 | BX4: 0.67430556 | CA4: Itzelh | CB4: 23679708 | CC4: 0.42222222 | CD4: 0.42361111 | CG4: Itzelh | CH4: 23708740 | CI4: 0.40208333 | CJ4: 0.40347222 | CL4: * | CM4: Itzel Carranza | CN4: 23706370 | CO4: 0.47986111 | CP4: 0.48125 | CR4: * | CS4: Itzel Carranza | CT4: 23775160 | CU4: 0.44305556 | CV4: 0.44444444 | CX4: * | CY4: Ana | CZ4: 23774532 | DA4: 0.45138889 | DB4: 0.45694444 | DP4: * | DQ4: Marisol | DR4: 24114178 | DS4: 0.54444444 | DT4: 0.54583333 | DU4: 0.54722222 | DW4: * | DX4: Irasema | DY4: 24130534 | DZ4: 0.47013889 | EA4: 0.47430556 | EB4: 0.475 | ED4: * | EE4: Danielly | EF4: 23261044 | EG4: 0.44444444 | EH4: 0.44722222 | EI4: 0.45694444 | EK4: * | EL4: Gloria | EM4: 24215758 | EN4: 0.45138889 | EO4: 0.45486111 | EP4: 0.45833333 | ES4: HECTOR | ET4: 24214946 | EU4: 0.43611111 | EV4: 0.44027778 | EW4: 0.44375 | EZ4: DANIELLY | FA4: 24255814 | FB4: 0.46736111 | FC4: 0.47013889 | FD4: 0.47916667 | FG4: HANIA | FH4: 24267112 | FI4: 0.41319444 | FJ4: 0.42083333 | FK4: 0.42430556 | FN4: DULCE | FO4: 24302978 | FP4: 0.775 | FQ4: 0.40486111 | FR4: 0.4125 | FU4: CAROLINA | FV4: 24332524 | FW4: 0.38125 | FX4: 0.40416667 | FY4: 0.40486111 | GB4: HANIA | GC4: 24359330 | GD4: 0.5 | GE4: 0.50208333 | GF4: 0.50416667 | GI4: DULCE | GJ4: 24395670 | GK4: 0.425 | GL4: 0.42916667 | GM4: 0.43402778 | GP4: EDNA | GQ4: 24409818 | GR4: 0.45486111 | GS4: 0.79027778 | GT4: 0.45833333 | GW4: MAYTE | GX4: 24428180 | GY4: 0.37708333 | GZ4: 0.39097222 | HA4: 0.39305556 | HD4: HECTOR | HE4: 24371460 | HF4: 0.45208333 | HG4: 0.45694444 | HH4: 0.46666667 | HK4: GLORIA | HL4: 24488246 | HM4: 0.34583333 | HN4: 0.35277778 | HO4: 0.36388889 | HR4: HANIA | HS4: 24562834 | HT4: 0.43472222 | HU4: 0.43680556 | HV4: 0.43888889 | HY4: HANIA | HZ4: 24662326 | IA4: 0.35625 | IB4: 0.3625 | IC4: 0.36319444 | IF4: MARISOL | IG4: 24737898 | IH4: 0.42222222 | II4: 0.42569444 | IJ4: 0.43541667 | IM4: HECTOR | IN4: 24708476 | IO4: 0.45277778 | IP4: 0.45486111 | IQ4: 0.45625 | IT4: KARINA | IU4: 24802282 | IV4: 0.60694444 | IW4: 0.61875 | IX4: 0.62916667 | JA4: HECTOR | JB4: 24268712 | JC4: 0.52013889 | JD4: 0.52152778 | JE4: 0.52708333 | JH4: JAEL | JI4: 24855266 | JJ4: 0.64236111 | JK4: 0.64444444 | JL4: 0.65138889 | JO4: LIDIA | JP4: 24868248 | JQ4: 0.35069444 | JR4: 0.35555556 | JS4: 0.37013889 | JV4: IRASEMA | JW4: 24814862 | JY4: 0.44375 | JZ4: 0.44444444
A5: Itzelh | B5: 23301606 | C5: 0.54652778 | D5: 0.55 | G5: Hector | H5: 23353032 | I5: 0.46805556 | J5: 0.47083333 | M5: Danielly | N5: 23377656 | O5: 0.41180556 | P5: 0.41319444 | S5: Carolina | T5: 23409884 | U5: 0.39583333 | V5: 0.39791667 | Y5: Dulce | Z5: 23436420 | AA5: 0.4125 | AB5: 0.41458333 | AE5: Danielly | AF5: 23461806 | AG5: 0.40694444 | AH5: 0.41041667 | AK5: Dulce | AL5: 23475308 | AM5: 0.42013889 | AN5: 0.42430556 | AQ5: Itzelh | AR5: 23527266 | AS5: 0.43611111 | AT5: 0.4375 | AW5: Marisol | AX5: 23564056 | AY5: 0.41388889 | AZ5: 0.41597222 | BC5: Fernanda | BD5: 23596692 | BE5: 0.40486111 | BF5: 0.40625 | BI5: Irasema | BJ5: 23615368 | BK5: 0.41388889 | BL5: 0.41736111 | BO5: Hania | BP5: 23646300 | BQ5: 0.40694444 | BR5: 0.40902778 | BU5: Dulce | BV5: 23659672 | BW5: 0.71458333 | BX5: 0.76319444 | CA5: Edna | CB5: 23678318 | CC5: 0.425 | CD5: 0.42638889 | CG5: Ana | CH5: 23709224 | CI5: 0.42291667 | CJ5: 0.425 | CL5: * | CM5: Hector | CN5: 23726144 | CO5: 0.43611111 | CP5: 0.43680556 | CR5: * | CS5: Hania | CT5: 23064204 | CU5: 0.48611111 | CV5: 0.48888889 | CX5: * | CY5: Hania | CZ5: 23662598 | DA5: 0.64791667 | DP5: * | DQ5: Irasema | DR5: 24115106 | DS5: 0.54583333 | DT5: 0.55416667 | DU5: 0.55486111 | DW5: * | DX5: Danielly | DY5: 24150794 | DZ5: 0.47222222 | EA5: 0.47569444 | EB5: 0.48611111 | ED5: * | EE5: Hania | EF5: 24179372 | EG5: 0.45416667 | EH5: 0.45694444 | EI5: 0.4625 | EK5: * | EL5: Hania | EM5: 24217048 | EN5: 0.46805556 | EO5: 0.49722222 | EP5: 0.49861111 | ES5: PAOLA | ET5: 23125936 | EU5: 0.43472222 | EV5: 0.45069444 | EW5: 0.45208333 | EZ5: ANA | FA5: 24230042 | FB5: 0.48819444 | FC5: 0.49444444 | FD5: 0.50347222 | FG5: HECTOR | FH5: 24272816 | FI5: 0.39930556 | FJ5: 0.42222222 | FK5: 0.42291667 | FN5: ITZELH | FO5: 24302664 | FP5: 0.77291667 | FQ5: 0.40694444 | FR5: 0.40902778 | FU5: MARISOL | FV5: 24324502 | FW5: 0.46180556 | FX5: 0.47361111 | FY5: 0.47638889 | GB5: LIDIA | GC5: 24315204 | GD5: 0.5125 | GE5: 0.51597222 | GF5: 0.52361111 | GI5: CAROLINA | GJ5: 24392654 | GK5: 0.43611111 | GL5: 0.43958333 | GM5: 0.44097222 | GP5: LIDIA | GQ5: 24408688 | GR5: 0.79027778 | GS5: 0.46180556 | GT5: 0.47708333 | GW5: DULCE | GX5: 24418318 | GY5: 0.43402778 | GZ5: 0.43541667 | HA5: 0.43819444 | HD5: HECTOR | HE5: 24471826 | HF5: 0.46944444 | HG5: 0.47152778 | HH5: 0.47291667 | HK5: GLORIA | HL5: 24463860 | HM5: 0.34583333 | HN5: 0.35 | HO5: 0.35347222 | HR5: PAOLA | HS5: 24558084 | HT5: 0.44027778 | HU5: 0.44305556 | HV5: 0.44444444 | HY5: CAROLINA | HZ5: 24663178 | IA5: 0.35833333 | IB5: 0.36805556 | IC5: 0.37291667 | IF5: BEATRIZ | IG5: 24696360 | IH5: 0.46319444 | II5: 0.46597222 | IJ5: 0.46527778 | IM5: FERNANDA | IN5: 24781244 | IO5: 0.49236111 | IP5: 0.49861111 | IQ5: 0.50486111 | IT5: HANIA | IU5: 24810288 | IV5: 0.60902778 | IW5: 0.62291667 | IX5: 0.625 | JA5: BEATRIZ | JB5: 24841244 | JC5: 0.66041667 | JD5: 0.66388889 | JE5: 0.66527778 | JH5: LUZ | JI5: 24855670 | JJ5: 0.64375 | JK5: 0.64583333 | JL5: 0.67777778 | JO5: DANIELLY | JP5: 24859664 | JQ5: 0.35208333 | JR5: 0.35347222 | JS5: 0.35486111 | JV5: MAYTE | JW5: 24926032 | JX5: 0.52430556 | JY5: 0.52847222 | JZ5: 0.53055556
A6: Carolina | B6: 23303760 | C6: 0.54861111 | D6: 0.56597222 | G6: Hector | H6: 23353820 | I6: 0.47222222 | J6: 0.475 | M6: Hector | N6: 23391100 | O6: 0.4125 | P6: 0.41388889 | S6: Danielly | T6: 23408896 | U6: 0.39791667 | V6: 0.4 | Y6: Miriam | Z6: 23440238 | AA6: 0.41666667 | AB6: 0.41805556 | AE6: Carolina | AF6: 23463790 | AG6: 0.41597222 | AH6: 0.42013889 | AK6: Carolina | AL6: 23492964 | AM6: 0.42152778 | AN6: 0.42638889 | AQ6: Edna | AR6: 23528922 | AS6: 0.43819444 | AT6: 0.44027778 | AW6: Melanie | AX6: 23556026 | AY6: 0.425 | AZ6: 0.44722222 | BC6: Dulce | BD6: 23581862 | BE6: 0.40763889 | BF6: 0.40902778 | BI6: Hania | BJ6: 23631334 | BK6: 0.41666667 | BL6: 0.41944444 | BO6: Hania | BP6: 23649522 | BQ6: 0.41041667 | BR6: 0.45069444 | BU6: Litzy | BV6: 23660004 | BW6: 0.61944444 | BX6: 0.62847222 | CA6: Danielly | CB6: 23677200 | CC6: 0.42986111 | CD6: 0.43194444 | CG6: Ana | CH6: 23712674 | CI6: 0.42430556 | CJ6: 0.42569444 | CL6: * | CM6: Melanie | CN6: 23761287 | CO6: 0.48819444 | CP6: 0.49236111 | CR6: * | CS6: Gabriela | CT6: 23795674 | CU6: 0.57083333 | CV6: 0.57430556 | CX6: * | CY6: Danielly | CZ6: 23819870 | DA6: 0.64652778 | DB6: 0.64930556 | DP6: * | DQ6: Karina | DR6: 24120922 | DS6: 0.60416667 | DT6: 0.60763889 | DU6: 0.62430556 | DW6: * | DX6: Hector | DY6: 23637202 | DZ6: 0.47291667 | EA6: 0.47708333 | EB6: 0.53263889 | ED6: * | EE6: Irasema | EF6: 24174758 | EG6: 0.46180556 | EH6: 0.46319444 | EI6: 0.46527778 | EK6: * | EL6: Paola | EM6: 24156074 | EN6: 0.50138889 | EO6: 0.50902778 | EP6: 0.51041667 | ES6: FERNANDA | ET6: 24230346 | EU6: 0.43194444 | EV6: 0.45972222 | EW6: 0.46319444 | EZ6: HECTOR | FA6: 19289310 | FB6: 0.48958333 | FC6: 0.49930556 | FD6: 0.50069444 | FG6: HANIA | FH6: 24282484 | FI6: 0.39375 | FJ6: 0.42361111 | FK6: 0.42638889 | FN6: DANIELLY | FO6: 24303880 | FP6: 0.40138889 | FQ6: 0.40972222 | FR6: 0.425 | FU6: CAROLINA | FV6: 24346560 | FW6: 0.47430556 | FX6: 0.47777778 | FY6: 0.47916667 | GB6: CAROLINA | GC6: 24369920 | GD6: 0.55694444 | GE6: 0.56319444 | GF6: 0.56388889 | GI6: DULCE | GJ6: 24386144 | GK6: 0.475 | GL6: 0.47777778 | GM6: 0.47916667 | GP6: EDNA | GQ6: 24406980 | GR6: 0.49791667 | GS6: 0.50277778 | GT6: 0.50416667 | GW6: DANIELLY | GX6: 24444508 | GY6: 0.45208333 | GZ6: 0.45833333 | HA6: 0.46388889 | HD6: YESSENIA | HE6: 24456608 | HF6: 0.47013889 | HG6: 0.47291667 | HH6: 0.475 | HK6: YESSENIA | HL6: 24497374 | HM6: 0.38055556 | HN6: 0.39444444 | HO6: 0.39583333 | HR6: GLORIA | HS6: 24636432 | HT6: 0.49444444 | HU6: 0.49652778 | HV6: 0.50069444 | HY6: MAGALI | HZ6: 24663452 | IA6: 0.41180556 | IB6: 0.41388889 | IC6: 0.41805556 | IF6: DANIELLY | IG6: 24712390 | IH6: 0.47569444 | II6: 0.47916667 | IJ6: 0.48333333 | IM6: PAOLA | IN6: 24754280 | IO6: 0.49652778 | IP6: 0.50069444 | IQ6: 0.50208333 | IT6: HANIA | IU6: 24488398 | IV6: 0.61041667 | IW6: 0.62430556 | IX6: 0.62569444 | JA6: ANDRE | JB6: 24834106 | JC6: 0.69097222 | JD6: 0.69444444 | JE6: 0.69652778 | JH6: PAOLA | JI6: 24854068 | JJ6: 0.63263889 | JK6: 0.64861111 | JL6: 0.64930556 | JO6: BEATRIZ | JP6: 24870536 | JQ6: 0.35277778 | JR6: 0.35763889 | JS6: 0.35972222 | JV6: LUZ | JW6: 24930576 | JX6: 0.55972222 | JY6: 0.56666667
A7: Melanie | B7: 23304336 | C7: 0.55277778 | D7: 0.56875 | G7: Itzelh | H7: 23320698 | I7: 0.49791667 | J7: 0.50069444 | M7: Itzelh | N7: 23378100 | O7: 0.41666667 | P7: 0.41875 | S7: Melanie | T7: 23410168 | U7: 0.40069444 | V7: 0.40416667 | Y7: Hania | Z7: 23446224 | AA7: 0.42361111 | AB7: 0.42569444 | AE7: Hania | AF7: 23463744 | AG7: 0.41944444 | AH7: 0.42083333 | AK7: Miriam | AL7: 23495726 | AM7: 0.425 | AN7: 0.425 | AQ7: Edna | AR7: 23533786 | AS7: 0.43958333 | AT7: 0.44027778 | AW7: Edna | AX7: 23562988 | AY7: 0.43819444 | AZ7: 0.43888889 | BC7: Itzelh | BD7: 23599104 | BE7: 0.41180556 | BF7: 0.41319444 | BI7: Fernanda | BJ7: 23617738 | BK7: 0.41805556 | BL7: 0.42152778 | BO7: Guadalupe | BP7: 23646692 | BQ7: 0.41805556 | BR7: 0.42083333 | BU7: Ana | BV7: 23660262 | BW7: 0.70486111 | BX7: 0.71319444 | CA7: Miriam | CB7: 23680836 | CC7: 0.43333333 | CD7: 0.43402778 | CG7: Itzelh | CH7: 23725514 | CI7: 0.42638889 | CJ7: 0.42847222 | CL7: * | CM7: Ana | CN7: 23762769 | CO7: 0.49930556 | CP7: 0.50138889 | CR7: * | CS7: Gabriela | CT7: 23694574 | CU7: 0.57222222 | CV7: 0.575 | CX7: * | CY7: Edna | CZ7: 23813562 | DA7: 0.69375 | DB7: 0.70555556 | DP7: * | DQ7: Gloria | DR7: 24118172 | DS7: 0.60416667 | DT7: 0.61111111 | DU7: 0.6125 | DW7: * | DX7: Ana | DY7: 24143942 | DZ7: 0.62222222 | EA7: 0.62361111 | EB7: 0.62777778 | ED7: * | EE7: Carolina | EF7: 24135746 | EG7: 0.46319444 | EH7: 0.46597222 | EI7: 0.46805556 | EK7: * | EL7: Paola | EM7: 24194094 | EN7: 0.52291667 | EO7: 0.52777778 | EP7: 0.53680556 | ES7: DANIELLY | ET7: 24244176 | EU7: 0.47916667 | EV7: 0.48263889 | EW7: 0.48472222 | EZ7: HECTOR | FA7: 24259562 | FB7: 0.51111111 | FC7: 0.51388889 | FD7: 0.51875 | FG7: HANIA | FH7: 24248096 | FI7: 0.38958333 | FJ7: 0.42569444 | FK7: 0.42777778 | FN7: MAGALI | FO7: 24306106 | FP7: 0.45416667 | FQ7: 0.46527778 | FR7: 0.46666667 | FU7: MARISOL | FV7: 24341216 | FW7: 0.47777778 | FX7: 0.47986111 | FY7: 0.48541667 | GB7: HANIA | GC7: 24361422 | GD7: 0.61111111 | GE7: 0.61597222 | GF7: 0.61875 | GI7: ITZEL CARRANZA | GJ7: 24386248 | GK7: 0.47708333 | GL7: 0.48055556 | GM7: 0.48611111 | GP7: DANIELA | GQ7: 24403818 | GR7: 0.51111111 | GS7: 0.51319444 | GT7: 0.51666667 | GW7: MAGALI | GX7: 24436594 | GY7: 0.44722222 | GZ7: 0.46041667 | HA7: 0.46180556 | HD7: LIDIA | HE7: 24140424 | HF7: 0.50277778 | HG7: 0.50416667 | HH7: 0.50972222 | HK7: HANIA | HL7: 24496366 | HM7: 0.34652778 | HN7: 0.35347222 | HO7: 0.35486111 | HR7: LIDIA | HS7: 24636206 | HT7: 0.51666667 | HU7: 0.52083333 | HV7: 0.53263889 | HY7: ANDRE | HZ7: 24663042 | IA7: 0.3625 | IB7: 0.36458333 | IC7: 0.36527778 | IF7: YESSENIA | IG7: 24708666 | IH7: 0.53611111 | II7: 0.53958333 | IJ7: 0.54305556 | IM7: HANIA | IN7: 24780510 | IO7: 0.49861111 | IP7: 0.50138889 | IQ7: 0.50416667 | IT7: GUADALUPE | IU7: 24811230 | IV7: 0.61944444 | IW7: 0.62638889 | IX7: 0.63055556 | JA7: LUIS | JB7: 24843042 | JC7: 0.75763889 | JD7: 0.75972222 | JE7: 0.76458333 | JH7: KATE | JI7: 24832226 | JJ7: 0.64513889 | JK7: 0.65069444 | JL7: X | JO7: MAYTE | JP7: 24872360 | JQ7: 0.35486111 | JR7: 0.36041667 | JS7: 0.36180556 | JV7: IRASEMA | JW7: 24814380 | JY7: 0.54722222 | JZ7: 0.58819444
A8: Magali | B8: 23315970 | C8: 0.55416667 | D8: 0.55833333 | G8: Melanie | H8: 23354314 | I8: 0.50486111 | J8: 0.51388889 | M8: Carolina | N8: 23366516 | O8: 0.42291667 | P8: 0.43194444 | S8: Magali | T8: 23411696 | U8: 0.40486111 | V8: 0.40694444 | Y8: Carolina | Z8: 23447794 | AA8: 0.43055556 | AB8: 0.43541667 | AE8: Hania | AF8: 23465238 | AG8: 0.42083333 | AH8: 0.42708333 | AK8: Carolina | AL8: 23496572 | AM8: 0.43055556 | AN8: 0.43402778 | AQ8: Hania | AR8: 23537976 | AS8: 0.44236111 | AT8: 0.44375 | AW8: Fernanda | AX8: 23571958 | AY8: 0.53194444 | AZ8: 0.53333333 | BC8: Adela | BD8: 23585834 | BE8: 0.43194444 | BF8: 0.44791667 | BI8: Dulce | BJ8: 23630392 | BK8: 0.42013889 | BL8: 0.42222222 | BO8: Litzy | BP8: 23646872 | BQ8: 0.42430556 | BR8: 0.42986111 | BU8: Gloria | BV8: 23661830 | BW8: 0.71111111 | BX8: 0.71388889 | CA8: Danielly | CB8: 23677662 | CC8: 0.43888889 | CD8: 0.43958333 | CG8: Carolina | CH8: 23727870 | CI8: 0.47013889 | CJ8: 0.47222222 | CL8: * | CM8: Paola | CN8: 23742131 | CO8: 0.56041667 | CP8: 0.5625 | CR8: * | CS8: Edna | CT8: 23798624 | CU8: 0.575 | CV8: 0.57777778 | DP8: * | DQ8: Hector | DR8: 24112100 | DS8: 0.61666667 | DT8: 0.62013889 | DU8: 0.63263889 | DW8: * | DX8: Gloria | DY8: 24155416 | DZ8: 0.62638889 | EA8: 0.64791667 | EB8: 0.65138889 | ED8: * | EE8: Itzelh | EF8: 24189214 | EG8: 0.46388889 | EH8: 0.46736111 | EI8: 0.47013889 | EK8: * | EL8: Ana | EM8: 24156734 | EN8: 0.52361111 | EO8: 0.52638889 | EP8: 0.54027778 | ES8: PAOLA | ET8: 24244458 | EU8: 0.48333333 | EV8: 0.48611111 | EW8: 0.4875 | EZ8: DANIELLY | FA8: 24258488 | FB8: 0.5125 | FC8: 0.51527778 | FD8: 0.52430556 | FG8: HECTOR | FH8: 24264720 | FI8: 0.42916667 | FJ8: 0.43263889 | FK8: 0.43402778 | FN8: KARINA | FO8: 24282658 | FP8: 0.48541667 | FQ8: 0.49097222 | FR8: 0.49861111 | FU8: HANIA | FV8: 24342088 | FW8: 0.47916667 | FX8: 0.48333333 | FY8: 0.48472222 | GB8: MARISOL | GC8: 24375688 | GD8: 0.62638889 | GE8: 0.63541667 | GF8: 0.64236111 | GI8: HECTOR | GJ8: 24397608 | GK8: 0.47291667 | GL8: 0.48333333 | GM8: 0.48541667 | GP8: LIDIA | GQ8: 23808686 | GR8: 0.54791667 | GS8: 0.54791667 | GT8: 0.55486111 | GW8: CAROLINA | GX8: 24436100 | GY8: 0.47013889 | GZ8: 0.47222222 | HA8: 0.47361111 | HD8: DANIELLY | HE8: 24194850 | HF8: 0.50416667 | HG8: 0.50694444 | HH8: 0.51597222 | HK8: HANIA | HL8: 24508078 | HM8: 0.34722222 | HN8: 0.35694444 | HO8: 0.35902778 | HR8: HANIA | HS8: 24506056 | HT8: 0.54166667 | HU8: 0.54444444 | HV8: 0.54652778 | HY8: IRASEMA | HZ8: 24560966 | IA8: 0.37569444 | IB8: 0.37638889 | IC8: 0.37708333 | IF8: EDNA | IG8: 24739472 | IH8: 0.56666667 | II8: 0.57291667 | IJ8: 0.57430556 | IM8: LIDIA | IN8: 24746116 | IO8: 0.5 | IP8: 0.50347222 | IQ8: 0.50555556 | IT8: MARISOL | IU8: 24798358 | IV8: 0.61180556 | IW8: 0.62916667 | IX8: 0.63055556 | JA8: CAROLINA | JB8: 24842778 | JC8: 0.78333333 | JD8: 0.78472222 | JE8: 0.78680556 | JH8: IRASEMA | JI8: 24845400 | JJ8: 0.64027778 | JK8: 0.65277778 | JL8: 0.65555556 | JO8: JAEL | JP8: 24863224 | JQ8: 0.44097222 | JR8: 0.44375 | JS8: 0.48819444
A9: Marisol | B9: 23316886 | C9: 0.55625 | D9: 0.5625 | G9: Magali | H9: 23354946 | I9: 0.50763889 | J9: 0.50902778 | M9: Hector | N9: 23387140 | O9: 0.42430556 | P9: 0.42986111 | S9: Marisol | T9: 23413818 | U9: 0.40972222 | V9: 0.41180556 | Y9: Edna | Z9: 23449984 | AA9: 0.43333333 | AB9: 0.43611111 | AE9: Dulce | AF9: 23449594 | AG9: 0.42291667 | AH9: 0.42777778 | AK9: Itzelh | AL9: 23505370 | AM9: 0.43819444 | AN9: 0.44027778 | AQ9: Carolina | AR9: 23529192 | AS9: 0.44375 | AT9: 0.44513889 | AW9: Melanie | AX9: 23572276 | AY9: 0.53819444 | AZ9: 0.55138889 | BC9: Edna | BD9: 22128172 | BE9: 0.43541667 | BF9: 0.43680556 | BI9: Marisol | BJ9: 23628198 | BK9: 0.42291667 | BL9: 0.42361111 | BO9: Litzy | BP9: 23645820 | BQ9: 0.42986111 | BR9: 0.43611111 | BU9: Danielly | BV9: 23663152 | BW9: 0.71388889 | BX9: 0.35972222 | CA9: Edna | CB9: 23682400 | CC9: 0.44236111 | CD9: 0.44375 | CG9: Ana | CH9: 23727890 | CI9: 0.47569444 | CJ9: 0.47847222 | CL9: * | CM9: Itzel Carranza | CN9: 23757641 | CO9: 0.5625 | CP9: 0.56527778 | CR9: * | CS9: Paola | CT9: 23795136 | CU9: 0.57847222 | CV9: 0.58333333 | DP9: * | DQ9: Karina | DR9: 24123358 | DS9: 0.62777778 | DT9: 0.65277778 | DU9: 0.66666667 | DW9: * | DX9: Hector | DY9: 24150934 | DZ9: 0.62708333 | EA9: 0.64930556 | EB9: 0.65138889 | ED9: * | EE9: Hector | EF9: 24175378 | EG9: 0.47569444 | EH9: 0.47708333 | EI9: 0.48541667 | EK9: * | EL9: Miriam | EM9: 23617548 | EN9: 0.54097222 | EO9: 0.54791667 | EP9: 0.54930556 | ES9: DULCE | ET9: 24206152 | EU9: 0.48611111 | EV9: 0.49097222 | EW9: 0.49375 | EZ9: DULCE | FA9: 24251922 | FB9: 0.74236111 | FC9: 0.50208333 | FD9: 0.53402778 | FG9: DANIELLY | FH9: 24274398 | FI9: 0.42569444 | FJ9: 0.4375 | FK9: 0.44375 | FN9: HECTOR | FO9: 24285520 | FP9: 0.49583333 | FQ9: 0.50208333 | FR9: 0.50555556 | FU9: ITZEL CARRANZA | FV9: 24346820 | FW9: 0.47986111 | FX9: 0.4875 | FY9: 0.48819444 | GB9: DULCE | GC9: 24376962 | GD9: 0.63958333 | GE9: 0.64513889 | GF9: 0.64791667 | GI9: MARISOL | GJ9: 24397820 | GK9: 0.48472222 | GL9: 0.48958333 | GM9: 0.49444444 | GW9: IRASEMA | GX9: 24436222 | GY9: 0.47083333 | GZ9: 0.475 | HA9: 0.47638889 | HD9: PAOLA | HE9: 24377376 | HF9: 0.51180556 | HG9: 0.52013889 | HH9: 0.52152778 | HK9: ANA | HL9: 24505658 | HM9: 0.34861111 | HN9: 0.35555556 | HO9: 0.36041667 | HR9: HECTOR | HS9: 24639144 | HT9: 0.54513889 | HU9: 0.54791667 | HV9: 0.55 | HY9: GLORIA | HZ9: 24648992 | IA9: 0.37222222 | IB9: 0.37291667 | IC9: 0.375 | IF9: CAROLINA | IG9: 24733372 | IH9: 0.56527778 | II9: 0.57430556 | IJ9: 0.57569444 | IM9: YESSENIA | IN9: 23555868 | IO9: 0.53402778 | IP9: 0.53611111 | IQ9: 0.53680556 | IT9: CAROLINA | IU9: 24512994 | IV9: 0.61597222 | IW9: 0.63125 | IX9: 0.63333333 | JH9: JAEL | JI9: 24848912 | JJ9: 0.64722222 | JK9: 0.65555556 | JL9: 0.66805556 | JO9: MAGALI | JP9: 24874688 | JQ9: 0.45763889 | JR9: 0.47986111 | JS9: 0.48055556
A10: Magali | B10: 23317238 | C10: 0.61319444 | D10: 0.61388889 | G10: Marisol | H10: 23356506 | I10: 0.52569444 | J10: 0.52777778 | M10: Melanie | N10: 23395518 | O10: 0.45 | P10: 0.45555556 | S10: Hania | T10: 23411008 | U10: 0.41597222 | V10: 0.425 | Y10: Itzelh | Z10: 23448778 | AA10: 0.43958333 | AB10: 0.44722222 | AE10: Miriam | AF10: 23472988 | AG10: 0.49583333 | AH10: 0.49791667 | AK10: Miriam | AL10: 23496458 | AM10: 0.45 | AN10: 0.45208333 | AQ10: Danielly | AR10: 23529120 | AS10: 0.45972222 | AT10: 0.46111111 | AW10: Hania | AX10: 23574330 | AY10: 0.59652778 | AZ10: 0.59930556 | BC10: Marisol | BD10: 23603210 | BE10: 0.44930556 | BF10: 0.45347222 | BI10: Irasema | BJ10: 23633758 | BK10: 0.45972222 | BL10: 0.46111111 | BO10: Guadalupe | BP10: 23645718 | BQ10: 0.43472222 | BR10: 0.45138889 | BU10: Ana | BV10: 23663760 | BW10: 0.63402778 | BX10: 0.63611111 | CA10: Ana | CB10: 23677336 | CC10: 0.44583333 | CD10: 0.44861111 | CG10: Hector | CH10: 23728198 | CI10: 0.49166667 | CJ10: 0.49444444 | CL10: * | CM10: Hector | CN10: 23766780 | CO10: 0.60138889 | CP10: 0.63958333 | CR10: * | CS10: Hector | CT10: 23729930 | CU10: 0.58125 | CV10: 0.58263889 | DP10: * | DQ10: Irasema | DR10: 24118148 | DS10: 0.65138889 | DT10: 0.65833333 | DU10: 0.65972222 | DW10: * | DX10: Itzelh | DY10: 24143988 | DZ10: 0.63402778 | EA10: 0.65138889 | EB10: 0.65277778 | ED10: * | EE10: Paola | EF10: 24179344 | EG10: 0.50208333 | EH10: 0.50486111 | EI10: 0.50763889 | EK10: * | EL10: Karina | EM10: 24207466 | EN10: 0.54722222 | EO10: 0.55277778 | EP10: 0.5625 | ES10: ITZEL CARRANZA | ET10: 24243322 | EU10: 0.49375 | EV10: 0.50208333 | EW10: 0.50555556 | EZ10: HECTOR | FA10: 24262416 | FB10: 0.54722222 | FC10: 0.54791667 | FD10: 0.55 | FG10: ITZELH | FH10: 24258240 | FI10: 0.37152778 | FJ10: 0.43958333 | FK10: 0.44861111 | FN10: HANIA | FO10: 24306348 | FP10: 0.50138889 | FQ10: 0.50347222 | FR10: 0.50555556 | FU10: CAROLINA | FV10: 24344264 | FW10: 0.48888889 | FX10: 0.49097222 | FY10: 0.49097222 | GB10: CAROLINA | GC10: 24378904 | GD10: 0.64166667 | GE10: 0.64861111 | GF10: 0.65 | GI10: DULCE | GJ10: 22591716 | GK10: 0.49375 | GL10: 0.49375 | GM10: 0.49930556 | GW10: ANA | GX10: 24174154 | GY10: 0.47222222 | GZ10: 0.47638889 | HA10: 0.47986111 | HD10: IRASEMA | HE10: 24140380 | HF10: 0.51527778 | HG10: 0.52222222 | HH10: 0.525 | HK10: HECTOR | HL10: 24507922 | HM10: 0.37291667 | HN10: 0.37222222 | HO10: 0.37430556 | HR10: MIRIAM | HS10: 24643024 | HT10: 0.68888889 | HU10: 0.69166667 | HV10: 0.69583333 | HY10: MIRIAM | HZ10: 24664610 | IA10: 0.37291667 | IB10: 0.375 | IC10: 0.37708333 | IF10: EDNA | IG10: 24733076 | IH10: 0.58055556 | II10: 0.58194444 | IJ10: 0.58333333 | IM10: MAGALI | IN10: 24754950 | IO10: 0.54583333 | IP10: 0.55 | IQ10: 0.58125 | IT10: KARINA | IU10: 24815046 | IV10: 0.63125 | IW10: 0.63541667 | IX10: 0.64097222 | JH10: PAOLA | JI10: 24852260 | JJ10: 0.65208333 | JK10: 0.65694444 | JL10: 0.67152778 | JO10: KARINA | JP10: 24885112 | JQ10: 0.47916667 | JR10: 0.48472222 | JS10: 0.49166667
